[93mWARNING [0m:   DEPRECATED FEATURE: flwr.client.start_numpy_client() is deprecated.
	Instead, use `flwr.client.start_client()` by ensuring you first call the `.to_client()` method as shown below:
	flwr.client.start_client(
		server_address='<IP>:<PORT>',
		client=FlowerClient().to_client(), # <-- where FlowerClient is of type flwr.client.NumPyClient object
	)
	Using `start_numpy_client()` is deprecated.

            This is a deprecated feature. It will be removed
            entirely in future versions of Flower.

[2025-04-11 01:10:54,960][flwr][WARNING] - DEPRECATED FEATURE: flwr.client.start_numpy_client() is deprecated.
	Instead, use `flwr.client.start_client()` by ensuring you first call the `.to_client()` method as shown below:
	flwr.client.start_client(
		server_address='<IP>:<PORT>',
		client=FlowerClient().to_client(), # <-- where FlowerClient is of type flwr.client.NumPyClient object
	)
	Using `start_numpy_client()` is deprecated.

            This is a deprecated feature. It will be removed
            entirely in future versions of Flower.

[32mINFO[0m:     127.0.0.1:50764 - "[1mGET /online HTTP/1.1[0m" [32m200 OK[0m
[93mWARNING [0m:   DEPRECATED FEATURE: flwr.client.start_client() is deprecated.
	Instead, use the `flower-supernode` CLI command to start a SuperNode as shown below:

		$ flower-supernode --insecure --superlink='<IP>:<PORT>'

	To view all available options, run:

		$ flower-supernode --help

	Using `start_client()` is deprecated.

            This is a deprecated feature. It will be removed
            entirely in future versions of Flower.

[2025-04-11 01:10:54,962][flwr][WARNING] - DEPRECATED FEATURE: flwr.client.start_client() is deprecated.
	Instead, use the `flower-supernode` CLI command to start a SuperNode as shown below:

		$ flower-supernode --insecure --superlink='<IP>:<PORT>'

	To view all available options, run:

		$ flower-supernode --help

	Using `start_client()` is deprecated.

            This is a deprecated feature. It will be removed
            entirely in future versions of Flower.

[2025-04-11 01:10:54,976][flwr][DEBUG] - Opened insecure gRPC connection (no certificates were passed)
[2025-04-11 01:10:54,979][flwr][DEBUG] - ChannelConnectivity.IDLE
[2025-04-11 01:10:54,981][flwr][DEBUG] - ChannelConnectivity.CONNECTING
[2025-04-11 01:10:54,983][flwr][DEBUG] - ChannelConnectivity.TRANSIENT_FAILURE
[2025-04-11 01:10:55,186][flwr][DEBUG] - gRPC channel closed
--- Logging error ---
Traceback (most recent call last):
  File "/home/ccl/safer/FedOps/MNIST/app.py", line 157, in fl_client_start
    await loop.run_in_executor(None, client_start)
  File "/home/ccl/anaconda3/envs/fedops_hyp/lib/python3.11/concurrent/futures/thread.py", line 58, in run
    result = self.fn(*self.args, **self.kwargs)
             ^^^^^^^^^^^^^^^^^^^^^^^^^^^^^^^^^^
  File "/home/ccl/anaconda3/envs/fedops_hyp/lib/python3.11/site-packages/flwr/client/app.py", line 731, in start_numpy_client
    start_client(
  File "/home/ccl/anaconda3/envs/fedops_hyp/lib/python3.11/site-packages/flwr/client/app.py", line 201, in start_client
    start_client_internal(
  File "/home/ccl/anaconda3/envs/fedops_hyp/lib/python3.11/site-packages/flwr/client/app.py", line 438, in start_client_internal
    message = receive()
              ^^^^^^^^^
  File "/home/ccl/anaconda3/envs/fedops_hyp/lib/python3.11/site-packages/flwr/client/grpc_client/connection.py", line 142, in receive
    proto = next(server_message_iterator)
            ^^^^^^^^^^^^^^^^^^^^^^^^^^^^^
  File "/home/ccl/anaconda3/envs/fedops_hyp/lib/python3.11/site-packages/grpc/_channel.py", line 543, in __next__
    return self._next()
           ^^^^^^^^^^^^
  File "/home/ccl/anaconda3/envs/fedops_hyp/lib/python3.11/site-packages/grpc/_channel.py", line 969, in _next
    raise self
grpc._channel._MultiThreadedRendezvous: <_MultiThreadedRendezvous of RPC that terminated with:
	status = StatusCode.UNAVAILABLE
	details = "failed to connect to all addresses; last error: UNAVAILABLE: ipv4:192.9.201.228:40025: Socket closed"
	debug_error_string = "UNKNOWN:Error received from peer  {created_time:"2025-04-11T01:10:54.983605682+09:00", grpc_status:14, grpc_message:"failed to connect to all addresses; last error: UNAVAILABLE: ipv4:192.9.201.228:40025: Socket closed"}"
>

During handling of the above exception, another exception occurred:

Traceback (most recent call last):
  File "/home/ccl/anaconda3/envs/fedops_hyp/lib/python3.11/logging/__init__.py", line 1110, in emit
    msg = self.format(record)
          ^^^^^^^^^^^^^^^^^^^
  File "/home/ccl/anaconda3/envs/fedops_hyp/lib/python3.11/logging/__init__.py", line 953, in format
    return fmt.format(record)
           ^^^^^^^^^^^^^^^^^^
  File "/home/ccl/anaconda3/envs/fedops_hyp/lib/python3.11/logging/__init__.py", line 687, in format
    record.message = record.getMessage()
                     ^^^^^^^^^^^^^^^^^^^
  File "/home/ccl/anaconda3/envs/fedops_hyp/lib/python3.11/logging/__init__.py", line 377, in getMessage
    msg = msg % self.args
          ~~~~^~~~~~~~~~~
TypeError: not all arguments converted during string formatting
Call stack:
  File "/home/ccl/safer/FedOps/MNIST/client_main.py", line 82, in <module>
    main()
  File "/home/ccl/anaconda3/envs/fedops_hyp/lib/python3.11/site-packages/hydra/main.py", line 94, in decorated_main
    _run_hydra(
  File "/home/ccl/anaconda3/envs/fedops_hyp/lib/python3.11/site-packages/hydra/_internal/utils.py", line 394, in _run_hydra
    _run_app(
  File "/home/ccl/anaconda3/envs/fedops_hyp/lib/python3.11/site-packages/hydra/_internal/utils.py", line 457, in _run_app
    run_and_report(
  File "/home/ccl/anaconda3/envs/fedops_hyp/lib/python3.11/site-packages/hydra/_internal/utils.py", line 220, in run_and_report
    return func()
  File "/home/ccl/anaconda3/envs/fedops_hyp/lib/python3.11/site-packages/hydra/_internal/utils.py", line 458, in <lambda>
    lambda: hydra.run(
  File "/home/ccl/anaconda3/envs/fedops_hyp/lib/python3.11/site-packages/hydra/_internal/hydra.py", line 119, in run
    ret = run_job(
  File "/home/ccl/anaconda3/envs/fedops_hyp/lib/python3.11/site-packages/hydra/core/utils.py", line 186, in run_job
    ret.return_value = task_function(task_cfg)
  File "/home/ccl/safer/FedOps/MNIST/client_main.py", line 78, in main
    fl_client.start()
  File "/home/ccl/safer/FedOps/MNIST/app.py", line 239, in start
    uvicorn.run(self.app, host='0.0.0.0', port=self.client_port)
  File "/home/ccl/anaconda3/envs/fedops_hyp/lib/python3.11/site-packages/uvicorn/main.py", line 579, in run
    server.run()
  File "/home/ccl/anaconda3/envs/fedops_hyp/lib/python3.11/site-packages/uvicorn/server.py", line 66, in run
    return asyncio.run(self.serve(sockets=sockets))
  File "/home/ccl/anaconda3/envs/fedops_hyp/lib/python3.11/asyncio/runners.py", line 190, in run
    return runner.run(main)
  File "/home/ccl/anaconda3/envs/fedops_hyp/lib/python3.11/asyncio/runners.py", line 118, in run
    return self._loop.run_until_complete(task)
  File "/home/ccl/anaconda3/envs/fedops_hyp/lib/python3.11/site-packages/uvicorn/protocols/http/httptools_impl.py", line 409, in run_asgi
    result = await app(  # type: ignore[func-returns-value]
  File "/home/ccl/anaconda3/envs/fedops_hyp/lib/python3.11/site-packages/uvicorn/middleware/proxy_headers.py", line 60, in __call__
    return await self.app(scope, receive, send)
  File "/home/ccl/anaconda3/envs/fedops_hyp/lib/python3.11/site-packages/fastapi/applications.py", line 1054, in __call__
    await super().__call__(scope, receive, send)
  File "/home/ccl/anaconda3/envs/fedops_hyp/lib/python3.11/site-packages/starlette/applications.py", line 112, in __call__
    await self.middleware_stack(scope, receive, send)
  File "/home/ccl/anaconda3/envs/fedops_hyp/lib/python3.11/site-packages/starlette/middleware/errors.py", line 165, in __call__
    await self.app(scope, receive, _send)
  File "/home/ccl/anaconda3/envs/fedops_hyp/lib/python3.11/site-packages/starlette/middleware/exceptions.py", line 62, in __call__
    await wrap_app_handling_exceptions(self.app, conn)(scope, receive, send)
  File "/home/ccl/anaconda3/envs/fedops_hyp/lib/python3.11/site-packages/starlette/_exception_handler.py", line 42, in wrapped_app
    await app(scope, receive, sender)
  File "/home/ccl/anaconda3/envs/fedops_hyp/lib/python3.11/site-packages/starlette/routing.py", line 714, in __call__
    await self.middleware_stack(scope, receive, send)
  File "/home/ccl/anaconda3/envs/fedops_hyp/lib/python3.11/site-packages/starlette/routing.py", line 734, in app
    await route.handle(scope, receive, send)
  File "/home/ccl/anaconda3/envs/fedops_hyp/lib/python3.11/site-packages/starlette/routing.py", line 288, in handle
    await self.app(scope, receive, send)
  File "/home/ccl/anaconda3/envs/fedops_hyp/lib/python3.11/site-packages/starlette/routing.py", line 76, in app
    await wrap_app_handling_exceptions(app, request)(scope, receive, send)
  File "/home/ccl/anaconda3/envs/fedops_hyp/lib/python3.11/site-packages/starlette/_exception_handler.py", line 42, in wrapped_app
    await app(scope, receive, sender)
  File "/home/ccl/anaconda3/envs/fedops_hyp/lib/python3.11/site-packages/starlette/routing.py", line 74, in app
    await response(scope, receive, send)
  File "/home/ccl/anaconda3/envs/fedops_hyp/lib/python3.11/site-packages/starlette/responses.py", line 160, in __call__
    await self.background()
  File "/home/ccl/anaconda3/envs/fedops_hyp/lib/python3.11/site-packages/starlette/background.py", line 41, in __call__
    await task()
  File "/home/ccl/anaconda3/envs/fedops_hyp/lib/python3.11/site-packages/starlette/background.py", line 26, in __call__
    await self.func(*self.args, **self.kwargs)
  File "/home/ccl/safer/FedOps/MNIST/app.py", line 196, in fl_client_start
    logging.info('[E][PC0002] learning', e)
Message: '[E][PC0002] learning'
Arguments: (<_MultiThreadedRendezvous of RPC that terminated with:
	status = StatusCode.UNAVAILABLE
	details = "failed to connect to all addresses; last error: UNAVAILABLE: ipv4:192.9.201.228:40025: Socket closed"
	debug_error_string = "UNKNOWN:Error received from peer  {created_time:"2025-04-11T01:10:54.983605682+09:00", grpc_status:14, grpc_message:"failed to connect to all addresses; last error: UNAVAILABLE: ipv4:192.9.201.228:40025: Socket closed"}"
>,)
--- Logging error ---
Traceback (most recent call last):
  File "/home/ccl/safer/FedOps/MNIST/app.py", line 157, in fl_client_start
    await loop.run_in_executor(None, client_start)
  File "/home/ccl/anaconda3/envs/fedops_hyp/lib/python3.11/concurrent/futures/thread.py", line 58, in run
    result = self.fn(*self.args, **self.kwargs)
             ^^^^^^^^^^^^^^^^^^^^^^^^^^^^^^^^^^
  File "/home/ccl/anaconda3/envs/fedops_hyp/lib/python3.11/site-packages/flwr/client/app.py", line 731, in start_numpy_client
    start_client(
  File "/home/ccl/anaconda3/envs/fedops_hyp/lib/python3.11/site-packages/flwr/client/app.py", line 201, in start_client
    start_client_internal(
  File "/home/ccl/anaconda3/envs/fedops_hyp/lib/python3.11/site-packages/flwr/client/app.py", line 438, in start_client_internal
    message = receive()
              ^^^^^^^^^
  File "/home/ccl/anaconda3/envs/fedops_hyp/lib/python3.11/site-packages/flwr/client/grpc_client/connection.py", line 142, in receive
    proto = next(server_message_iterator)
            ^^^^^^^^^^^^^^^^^^^^^^^^^^^^^
  File "/home/ccl/anaconda3/envs/fedops_hyp/lib/python3.11/site-packages/grpc/_channel.py", line 543, in __next__
    return self._next()
           ^^^^^^^^^^^^
  File "/home/ccl/anaconda3/envs/fedops_hyp/lib/python3.11/site-packages/grpc/_channel.py", line 969, in _next
    raise self
grpc._channel._MultiThreadedRendezvous: <_MultiThreadedRendezvous of RPC that terminated with:
	status = StatusCode.UNAVAILABLE
	details = "failed to connect to all addresses; last error: UNAVAILABLE: ipv4:192.9.201.228:40025: Socket closed"
	debug_error_string = "UNKNOWN:Error received from peer  {created_time:"2025-04-11T01:10:54.983605682+09:00", grpc_status:14, grpc_message:"failed to connect to all addresses; last error: UNAVAILABLE: ipv4:192.9.201.228:40025: Socket closed"}"
>

During handling of the above exception, another exception occurred:

Traceback (most recent call last):
  File "/home/ccl/anaconda3/envs/fedops_hyp/lib/python3.11/logging/__init__.py", line 1110, in emit
    msg = self.format(record)
          ^^^^^^^^^^^^^^^^^^^
  File "/home/ccl/anaconda3/envs/fedops_hyp/lib/python3.11/logging/__init__.py", line 953, in format
    return fmt.format(record)
           ^^^^^^^^^^^^^^^^^^
  File "/home/ccl/anaconda3/envs/fedops_hyp/lib/python3.11/logging/__init__.py", line 687, in format
    record.message = record.getMessage()
                     ^^^^^^^^^^^^^^^^^^^
  File "/home/ccl/anaconda3/envs/fedops_hyp/lib/python3.11/logging/__init__.py", line 377, in getMessage
    msg = msg % self.args
          ~~~~^~~~~~~~~~~
TypeError: not all arguments converted during string formatting
Call stack:
  File "/home/ccl/safer/FedOps/MNIST/client_main.py", line 82, in <module>
    main()
  File "/home/ccl/anaconda3/envs/fedops_hyp/lib/python3.11/site-packages/hydra/main.py", line 94, in decorated_main
    _run_hydra(
  File "/home/ccl/anaconda3/envs/fedops_hyp/lib/python3.11/site-packages/hydra/_internal/utils.py", line 394, in _run_hydra
    _run_app(
  File "/home/ccl/anaconda3/envs/fedops_hyp/lib/python3.11/site-packages/hydra/_internal/utils.py", line 457, in _run_app
    run_and_report(
  File "/home/ccl/anaconda3/envs/fedops_hyp/lib/python3.11/site-packages/hydra/_internal/utils.py", line 220, in run_and_report
    return func()
  File "/home/ccl/anaconda3/envs/fedops_hyp/lib/python3.11/site-packages/hydra/_internal/utils.py", line 458, in <lambda>
    lambda: hydra.run(
  File "/home/ccl/anaconda3/envs/fedops_hyp/lib/python3.11/site-packages/hydra/_internal/hydra.py", line 119, in run
    ret = run_job(
  File "/home/ccl/anaconda3/envs/fedops_hyp/lib/python3.11/site-packages/hydra/core/utils.py", line 186, in run_job
    ret.return_value = task_function(task_cfg)
  File "/home/ccl/safer/FedOps/MNIST/client_main.py", line 78, in main
    fl_client.start()
  File "/home/ccl/safer/FedOps/MNIST/app.py", line 239, in start
    uvicorn.run(self.app, host='0.0.0.0', port=self.client_port)
  File "/home/ccl/anaconda3/envs/fedops_hyp/lib/python3.11/site-packages/uvicorn/main.py", line 579, in run
    server.run()
  File "/home/ccl/anaconda3/envs/fedops_hyp/lib/python3.11/site-packages/uvicorn/server.py", line 66, in run
    return asyncio.run(self.serve(sockets=sockets))
  File "/home/ccl/anaconda3/envs/fedops_hyp/lib/python3.11/asyncio/runners.py", line 190, in run
    return runner.run(main)
  File "/home/ccl/anaconda3/envs/fedops_hyp/lib/python3.11/asyncio/runners.py", line 118, in run
    return self._loop.run_until_complete(task)
  File "/home/ccl/anaconda3/envs/fedops_hyp/lib/python3.11/site-packages/uvicorn/protocols/http/httptools_impl.py", line 409, in run_asgi
    result = await app(  # type: ignore[func-returns-value]
  File "/home/ccl/anaconda3/envs/fedops_hyp/lib/python3.11/site-packages/uvicorn/middleware/proxy_headers.py", line 60, in __call__
    return await self.app(scope, receive, send)
  File "/home/ccl/anaconda3/envs/fedops_hyp/lib/python3.11/site-packages/fastapi/applications.py", line 1054, in __call__
    await super().__call__(scope, receive, send)
  File "/home/ccl/anaconda3/envs/fedops_hyp/lib/python3.11/site-packages/starlette/applications.py", line 112, in __call__
    await self.middleware_stack(scope, receive, send)
  File "/home/ccl/anaconda3/envs/fedops_hyp/lib/python3.11/site-packages/starlette/middleware/errors.py", line 165, in __call__
    await self.app(scope, receive, _send)
  File "/home/ccl/anaconda3/envs/fedops_hyp/lib/python3.11/site-packages/starlette/middleware/exceptions.py", line 62, in __call__
    await wrap_app_handling_exceptions(self.app, conn)(scope, receive, send)
  File "/home/ccl/anaconda3/envs/fedops_hyp/lib/python3.11/site-packages/starlette/_exception_handler.py", line 42, in wrapped_app
    await app(scope, receive, sender)
  File "/home/ccl/anaconda3/envs/fedops_hyp/lib/python3.11/site-packages/starlette/routing.py", line 714, in __call__
    await self.middleware_stack(scope, receive, send)
  File "/home/ccl/anaconda3/envs/fedops_hyp/lib/python3.11/site-packages/starlette/routing.py", line 734, in app
    await route.handle(scope, receive, send)
  File "/home/ccl/anaconda3/envs/fedops_hyp/lib/python3.11/site-packages/starlette/routing.py", line 288, in handle
    await self.app(scope, receive, send)
  File "/home/ccl/anaconda3/envs/fedops_hyp/lib/python3.11/site-packages/starlette/routing.py", line 76, in app
    await wrap_app_handling_exceptions(app, request)(scope, receive, send)
  File "/home/ccl/anaconda3/envs/fedops_hyp/lib/python3.11/site-packages/starlette/_exception_handler.py", line 42, in wrapped_app
    await app(scope, receive, sender)
  File "/home/ccl/anaconda3/envs/fedops_hyp/lib/python3.11/site-packages/starlette/routing.py", line 74, in app
    await response(scope, receive, send)
  File "/home/ccl/anaconda3/envs/fedops_hyp/lib/python3.11/site-packages/starlette/responses.py", line 160, in __call__
    await self.background()
  File "/home/ccl/anaconda3/envs/fedops_hyp/lib/python3.11/site-packages/starlette/background.py", line 41, in __call__
    await task()
  File "/home/ccl/anaconda3/envs/fedops_hyp/lib/python3.11/site-packages/starlette/background.py", line 26, in __call__
    await self.func(*self.args, **self.kwargs)
  File "/home/ccl/safer/FedOps/MNIST/app.py", line 196, in fl_client_start
    logging.info('[E][PC0002] learning', e)
Message: '[E][PC0002] learning'
Arguments: (<_MultiThreadedRendezvous of RPC that terminated with:
	status = StatusCode.UNAVAILABLE
	details = "failed to connect to all addresses; last error: UNAVAILABLE: ipv4:192.9.201.228:40025: Socket closed"
	debug_error_string = "UNKNOWN:Error received from peer  {created_time:"2025-04-11T01:10:54.983605682+09:00", grpc_status:14, grpc_message:"failed to connect to all addresses; last error: UNAVAILABLE: ipv4:192.9.201.228:40025: Socket closed"}"
>,)
[2025-04-11 01:10:55,212][root][INFO] - notify_fail start
[2025-04-11 01:10:55,232][root][ERROR] - trainFin
[31mERROR[0m:    Exception in ASGI application
Traceback (most recent call last):
  File "/home/ccl/anaconda3/envs/fedops_hyp/lib/python3.11/site-packages/uvicorn/protocols/http/httptools_impl.py", line 409, in run_asgi
    result = await app(  # type: ignore[func-returns-value]
             ^^^^^^^^^^^^^^^^^^^^^^^^^^^^^^^^^^^^^^^^^^^^^^
  File "/home/ccl/anaconda3/envs/fedops_hyp/lib/python3.11/site-packages/uvicorn/middleware/proxy_headers.py", line 60, in __call__
    return await self.app(scope, receive, send)
           ^^^^^^^^^^^^^^^^^^^^^^^^^^^^^^^^^^^^
  File "/home/ccl/anaconda3/envs/fedops_hyp/lib/python3.11/site-packages/fastapi/applications.py", line 1054, in __call__
    await super().__call__(scope, receive, send)
  File "/home/ccl/anaconda3/envs/fedops_hyp/lib/python3.11/site-packages/starlette/applications.py", line 112, in __call__
    await self.middleware_stack(scope, receive, send)
  File "/home/ccl/anaconda3/envs/fedops_hyp/lib/python3.11/site-packages/starlette/middleware/errors.py", line 187, in __call__
    raise exc
  File "/home/ccl/anaconda3/envs/fedops_hyp/lib/python3.11/site-packages/starlette/middleware/errors.py", line 165, in __call__
    await self.app(scope, receive, _send)
  File "/home/ccl/anaconda3/envs/fedops_hyp/lib/python3.11/site-packages/starlette/middleware/exceptions.py", line 62, in __call__
    await wrap_app_handling_exceptions(self.app, conn)(scope, receive, send)
  File "/home/ccl/anaconda3/envs/fedops_hyp/lib/python3.11/site-packages/starlette/_exception_handler.py", line 53, in wrapped_app
    raise exc
  File "/home/ccl/anaconda3/envs/fedops_hyp/lib/python3.11/site-packages/starlette/_exception_handler.py", line 42, in wrapped_app
    await app(scope, receive, sender)
  File "/home/ccl/anaconda3/envs/fedops_hyp/lib/python3.11/site-packages/starlette/routing.py", line 714, in __call__
    await self.middleware_stack(scope, receive, send)
  File "/home/ccl/anaconda3/envs/fedops_hyp/lib/python3.11/site-packages/starlette/routing.py", line 734, in app
    await route.handle(scope, receive, send)
  File "/home/ccl/anaconda3/envs/fedops_hyp/lib/python3.11/site-packages/starlette/routing.py", line 288, in handle
    await self.app(scope, receive, send)
  File "/home/ccl/anaconda3/envs/fedops_hyp/lib/python3.11/site-packages/starlette/routing.py", line 76, in app
    await wrap_app_handling_exceptions(app, request)(scope, receive, send)
  File "/home/ccl/anaconda3/envs/fedops_hyp/lib/python3.11/site-packages/starlette/_exception_handler.py", line 53, in wrapped_app
    raise exc
  File "/home/ccl/anaconda3/envs/fedops_hyp/lib/python3.11/site-packages/starlette/_exception_handler.py", line 42, in wrapped_app
    await app(scope, receive, sender)
  File "/home/ccl/anaconda3/envs/fedops_hyp/lib/python3.11/site-packages/starlette/routing.py", line 74, in app
    await response(scope, receive, send)
  File "/home/ccl/anaconda3/envs/fedops_hyp/lib/python3.11/site-packages/starlette/responses.py", line 160, in __call__
    await self.background()
  File "/home/ccl/anaconda3/envs/fedops_hyp/lib/python3.11/site-packages/starlette/background.py", line 41, in __call__
    await task()
  File "/home/ccl/anaconda3/envs/fedops_hyp/lib/python3.11/site-packages/starlette/background.py", line 26, in __call__
    await self.func(*self.args, **self.kwargs)
  File "/home/ccl/safer/FedOps/MNIST/app.py", line 199, in fl_client_start
    raise e
  File "/home/ccl/safer/FedOps/MNIST/app.py", line 157, in fl_client_start
    await loop.run_in_executor(None, client_start)
  File "/home/ccl/anaconda3/envs/fedops_hyp/lib/python3.11/concurrent/futures/thread.py", line 58, in run
    result = self.fn(*self.args, **self.kwargs)
             ^^^^^^^^^^^^^^^^^^^^^^^^^^^^^^^^^^
  File "/home/ccl/anaconda3/envs/fedops_hyp/lib/python3.11/site-packages/flwr/client/app.py", line 731, in start_numpy_client
    start_client(
  File "/home/ccl/anaconda3/envs/fedops_hyp/lib/python3.11/site-packages/flwr/client/app.py", line 201, in start_client
    start_client_internal(
  File "/home/ccl/anaconda3/envs/fedops_hyp/lib/python3.11/site-packages/flwr/client/app.py", line 438, in start_client_internal
    message = receive()
              ^^^^^^^^^
  File "/home/ccl/anaconda3/envs/fedops_hyp/lib/python3.11/site-packages/flwr/client/grpc_client/connection.py", line 142, in receive
    proto = next(server_message_iterator)
            ^^^^^^^^^^^^^^^^^^^^^^^^^^^^^
  File "/home/ccl/anaconda3/envs/fedops_hyp/lib/python3.11/site-packages/grpc/_channel.py", line 543, in __next__
    return self._next()
           ^^^^^^^^^^^^
  File "/home/ccl/anaconda3/envs/fedops_hyp/lib/python3.11/site-packages/grpc/_channel.py", line 969, in _next
    raise self
grpc._channel._MultiThreadedRendezvous: <_MultiThreadedRendezvous of RPC that terminated with:
	status = StatusCode.UNAVAILABLE
	details = "failed to connect to all addresses; last error: UNAVAILABLE: ipv4:192.9.201.228:40025: Socket closed"
	debug_error_string = "UNKNOWN:Error received from peer  {created_time:"2025-04-11T01:10:54.983605682+09:00", grpc_status:14, grpc_message:"failed to connect to all addresses; last error: UNAVAILABLE: ipv4:192.9.201.228:40025: Socket closed"}"
>
[32mINFO[0m:     127.0.0.1:52372 - "[1mGET /online HTTP/1.1[0m" [32m200 OK[0m
[32mINFO[0m:     127.0.0.1:49942 - "[1mGET /online HTTP/1.1[0m" [32m200 OK[0m
[32mINFO[0m:     127.0.0.1:49948 - "[1mGET /online HTTP/1.1[0m" [32m200 OK[0m
[32mINFO[0m:     127.0.0.1:56686 - "[1mGET /online HTTP/1.1[0m" [32m200 OK[0m
[32mINFO[0m:     127.0.0.1:56702 - "[1mGET /online HTTP/1.1[0m" [32m200 OK[0m
[32mINFO[0m:     127.0.0.1:51866 - "[1mGET /online HTTP/1.1[0m" [32m200 OK[0m
[32mINFO[0m:     127.0.0.1:46324 - "[1mGET /online HTTP/1.1[0m" [32m200 OK[0m
[32mINFO[0m:     127.0.0.1:46340 - "[1mGET /online HTTP/1.1[0m" [32m200 OK[0m
[32mINFO[0m:     127.0.0.1:47932 - "[1mGET /online HTTP/1.1[0m" [32m200 OK[0m
[32mINFO[0m:     127.0.0.1:53984 - "[1mGET /online HTTP/1.1[0m" [32m200 OK[0m
[32mINFO[0m:     127.0.0.1:53996 - "[1mGET /online HTTP/1.1[0m" [32m200 OK[0m
[32mINFO[0m:     127.0.0.1:44258 - "[1mGET /online HTTP/1.1[0m" [32m200 OK[0m
[32mINFO[0m:     127.0.0.1:46908 - "[1mGET /online HTTP/1.1[0m" [32m200 OK[0m
[32mINFO[0m:     127.0.0.1:46922 - "[1mGET /online HTTP/1.1[0m" [32m200 OK[0m
[32mINFO[0m:     127.0.0.1:52436 - "[1mGET /online HTTP/1.1[0m" [32m200 OK[0m
[2025-04-11 01:12:37,515][root][INFO] - bulid model
[2025-04-11 01:12:37,516][root][INFO] - FL start
Response: {"task_id":"mnist","port":40025}
Response JSON: {'task_id': 'mnist', 'port': 40025}
[2025-04-11 01:12:37,525][client_api][INFO] - FL_server_IP:port - ccl.gachon.ac.kr:40025
[32mINFO[0m:     127.0.0.1:52446 - "[1mPOST /start HTTP/1.1[0m" [32m200 OK[0m
[2025-04-11 01:12:37,526][root][INFO] - FL learning ready
[2025-04-11 01:12:37,527][root][INFO] - fl_task_id: mnist
[2025-04-11 01:12:37,527][root][INFO] - dataset: MNIST
[2025-04-11 01:12:37,527][root][INFO] - output_size: 10
[2025-04-11 01:12:37,528][root][INFO] - validation_split: 0.2
[2025-04-11 01:12:37,528][root][INFO] - model_type: hyperparameter
[2025-04-11 01:12:37,528][root][INFO] - wandb_key: 38f6cf3c2c37660d42ebfe8ab434b72d34be3b31
[2025-04-11 01:12:37,529][root][INFO] - wandb_account: rirakang@gachon.ac.kr
[34m[1mwandb[0m: [33mWARNING[0m Calling wandb.login() after wandb.init() has no effect.
[93mWARNING [0m:   DEPRECATED FEATURE: flwr.client.start_numpy_client() is deprecated.
	Instead, use `flwr.client.start_client()` by ensuring you first call the `.to_client()` method as shown below:
	flwr.client.start_client(
		server_address='<IP>:<PORT>',
		client=FlowerClient().to_client(), # <-- where FlowerClient is of type flwr.client.NumPyClient object
	)
	Using `start_numpy_client()` is deprecated.

            This is a deprecated feature. It will be removed
            entirely in future versions of Flower.

[2025-04-11 01:12:37,535][flwr][WARNING] - DEPRECATED FEATURE: flwr.client.start_numpy_client() is deprecated.
	Instead, use `flwr.client.start_client()` by ensuring you first call the `.to_client()` method as shown below:
	flwr.client.start_client(
		server_address='<IP>:<PORT>',
		client=FlowerClient().to_client(), # <-- where FlowerClient is of type flwr.client.NumPyClient object
	)
	Using `start_numpy_client()` is deprecated.

            This is a deprecated feature. It will be removed
            entirely in future versions of Flower.

[93mWARNING [0m:   DEPRECATED FEATURE: flwr.client.start_client() is deprecated.
	Instead, use the `flower-supernode` CLI command to start a SuperNode as shown below:

		$ flower-supernode --insecure --superlink='<IP>:<PORT>'

	To view all available options, run:

		$ flower-supernode --help

	Using `start_client()` is deprecated.

            This is a deprecated feature. It will be removed
            entirely in future versions of Flower.

[2025-04-11 01:12:37,536][flwr][WARNING] - DEPRECATED FEATURE: flwr.client.start_client() is deprecated.
	Instead, use the `flower-supernode` CLI command to start a SuperNode as shown below:

		$ flower-supernode --insecure --superlink='<IP>:<PORT>'

	To view all available options, run:

		$ flower-supernode --help

	Using `start_client()` is deprecated.

            This is a deprecated feature. It will be removed
            entirely in future versions of Flower.

[2025-04-11 01:12:37,538][flwr][DEBUG] - Opened insecure gRPC connection (no certificates were passed)
[2025-04-11 01:12:37,543][flwr][DEBUG] - ChannelConnectivity.IDLE
[2025-04-11 01:12:37,544][flwr][DEBUG] - ChannelConnectivity.CONNECTING
[2025-04-11 01:12:37,547][flwr][DEBUG] - ChannelConnectivity.READY
[32mINFO[0m:     127.0.0.1:52144 - "[1mGET /online HTTP/1.1[0m" [32m200 OK[0m
[32mINFO[0m:     127.0.0.1:39632 - "[1mGET /online HTTP/1.1[0m" [32m200 OK[0m
