[2025-04-08 13:12:11,255][root][INFO] - FL_Task - {"dataset": "MNIST", "start_execution_time": "2025-04-08 13:12:11"}
[2025-04-08 13:12:11,317][__main__][INFO] - data loaded
[2025-04-08 13:12:11,342][root][INFO] - init model_type: Pytorch
[2025-04-08 13:12:18,633][root][INFO] - bulid model
[2025-04-08 13:12:18,633][root][INFO] - FL start
[2025-04-08 13:12:18,641][client_api][INFO] - FL_server_IP:port - ccl.gachon.ac.kr:40025
[2025-04-08 13:12:18,643][root][INFO] - FL learning ready
[2025-04-08 13:12:18,643][root][INFO] - fl_task_id: mnist
[2025-04-08 13:12:18,643][root][INFO] - dataset: MNIST
[2025-04-08 13:12:18,643][root][INFO] - output_size: 10
[2025-04-08 13:12:18,643][root][INFO] - validation_split: 0.2
[2025-04-08 13:12:18,643][root][INFO] - model_type: Pytorch
[2025-04-08 13:12:18,643][root][INFO] - wandb_key: 38f6cf3c2c37660d42ebfe8ab434b72d34be3b31
[2025-04-08 13:12:18,644][root][INFO] - wandb_account: rirakang@gachon.ac.kr
[2025-04-08 13:12:20,288][flwr][WARNING] - DEPRECATED FEATURE: flwr.client.start_numpy_client() is deprecated. 
	Instead, use `flwr.client.start_client()` by ensuring you first call the `.to_client()` method as shown below: 
	flwr.client.start_client(
		server_address='<IP>:<PORT>',
		client=FlowerClient().to_client(), # <-- where FlowerClient is of type flwr.client.NumPyClient object
	)
	Using `start_numpy_client()` is deprecated.

            This is a deprecated feature. It will be removed
            entirely in future versions of Flower.
        
[2025-04-08 13:12:20,289][flwr][WARNING] - DEPRECATED FEATURE: flwr.client.start_client() is deprecated.
	Instead, use the `flower-supernode` CLI command to start a SuperNode as shown below:

		$ flower-supernode --insecure --superlink='<IP>:<PORT>'

	To view all available options, run:

		$ flower-supernode --help

	Using `start_client()` is deprecated.

            This is a deprecated feature. It will be removed
            entirely in future versions of Flower.
        
[2025-04-08 13:12:20,303][flwr][DEBUG] - Opened insecure gRPC connection (no certificates were passed)
[2025-04-08 13:12:20,306][flwr][DEBUG] - ChannelConnectivity.IDLE
[2025-04-08 13:12:20,307][flwr][DEBUG] - ChannelConnectivity.CONNECTING
[2025-04-08 13:12:20,311][flwr][DEBUG] - ChannelConnectivity.READY
[2025-04-08 13:12:22,357][flwr][INFO] - 
[2025-04-08 13:12:22,358][flwr][INFO] - Received: train message b2c9861c-70be-4c9f-a923-2dbf05a3f808
[2025-04-08 13:12:22,372][flwr][ERROR] - Client raised an exception.
Traceback (most recent call last):
  File "/home/ccl/anaconda3/envs/fedops_hyp/lib/python3.11/site-packages/flwr/client/app.py", line 571, in start_client_internal
    reply_message = client_app(message=message, context=context)
                    ^^^^^^^^^^^^^^^^^^^^^^^^^^^^^^^^^^^^^^^^^^^^
  File "/home/ccl/anaconda3/envs/fedops_hyp/lib/python3.11/site-packages/flwr/client/client_app.py", line 144, in __call__
    return self._call(message, context)
           ^^^^^^^^^^^^^^^^^^^^^^^^^^^^
  File "/home/ccl/anaconda3/envs/fedops_hyp/lib/python3.11/site-packages/flwr/client/client_app.py", line 128, in ffn
    out_message = handle_legacy_message_from_msgtype(
                  ^^^^^^^^^^^^^^^^^^^^^^^^^^^^^^^^^^^
  File "/home/ccl/anaconda3/envs/fedops_hyp/lib/python3.11/site-packages/flwr/client/message_handler/message_handler.py", line 128, in handle_legacy_message_from_msgtype
    fit_res = maybe_call_fit(
              ^^^^^^^^^^^^^^^
  File "/home/ccl/anaconda3/envs/fedops_hyp/lib/python3.11/site-packages/flwr/client/client.py", line 224, in maybe_call_fit
    return client.fit(fit_ins)
           ^^^^^^^^^^^^^^^^^^^
  File "/home/ccl/anaconda3/envs/fedops_hyp/lib/python3.11/site-packages/flwr/client/numpy_client.py", line 227, in _fit
    results = self.numpy_client.fit(parameters, ins.config)  # type: ignore
              ^^^^^^^^^^^^^^^^^^^^^^^^^^^^^^^^^^^^^^^^^^^^^
  File "/home/ccl/safer/FedOps/MNIST/client_fl.py", line 128, in fit
    lr : int = config["learning_rate"]
               ~~~~~~^^^^^^^^^^^^^^^^^
  File "/home/ccl/anaconda3/envs/fedops_hyp/lib/python3.11/site-packages/flwr/common/record/typeddict.py", line 50, in __getitem__
    return cast(dict[K, V], self.__dict__["_data"])[item]
           ~~~~~~~~~~~~~~~~~~~~~~~~~~~~~~~~~~~~~~~~^^^^^^
KeyError: 'learning_rate'
[2025-04-08 13:12:22,557][flwr][DEBUG] - gRPC channel closed
[2025-04-08 13:12:22,588][root][INFO] - notify_fail start
[2025-04-08 13:12:22,606][root][ERROR] - trainFin
[2025-04-08 13:19:38,428][root][INFO] - ccl-e-server;b0:7b:25:0e:e7:96-client close
