[93mWARNING [0m:   DEPRECATED FEATURE: flwr.client.start_numpy_client() is deprecated.
	Instead, use `flwr.client.start_client()` by ensuring you first call the `.to_client()` method as shown below:
	flwr.client.start_client(
		server_address='<IP>:<PORT>',
		client=FlowerClient().to_client(), # <-- where FlowerClient is of type flwr.client.NumPyClient object
	)
	Using `start_numpy_client()` is deprecated.

            This is a deprecated feature. It will be removed
            entirely in future versions of Flower.

[2025-04-10 14:09:22,237][flwr][WARNING] - DEPRECATED FEATURE: flwr.client.start_numpy_client() is deprecated.
	Instead, use `flwr.client.start_client()` by ensuring you first call the `.to_client()` method as shown below:
	flwr.client.start_client(
		server_address='<IP>:<PORT>',
		client=FlowerClient().to_client(), # <-- where FlowerClient is of type flwr.client.NumPyClient object
	)
	Using `start_numpy_client()` is deprecated.

            This is a deprecated feature. It will be removed
            entirely in future versions of Flower.

[93mWARNING [0m:   DEPRECATED FEATURE: flwr.client.start_client() is deprecated.
	Instead, use the `flower-supernode` CLI command to start a SuperNode as shown below:

		$ flower-supernode --insecure --superlink='<IP>:<PORT>'

	To view all available options, run:

		$ flower-supernode --help

	Using `start_client()` is deprecated.

            This is a deprecated feature. It will be removed
            entirely in future versions of Flower.

[2025-04-10 14:09:22,239][flwr][WARNING] - DEPRECATED FEATURE: flwr.client.start_client() is deprecated.
	Instead, use the `flower-supernode` CLI command to start a SuperNode as shown below:

		$ flower-supernode --insecure --superlink='<IP>:<PORT>'

	To view all available options, run:

		$ flower-supernode --help

	Using `start_client()` is deprecated.

            This is a deprecated feature. It will be removed
            entirely in future versions of Flower.

[2025-04-10 14:09:22,253][flwr][DEBUG] - Opened insecure gRPC connection (no certificates were passed)
[2025-04-10 14:09:22,257][flwr][DEBUG] - ChannelConnectivity.IDLE
[2025-04-10 14:09:22,258][flwr][DEBUG] - ChannelConnectivity.CONNECTING
[2025-04-10 14:09:22,263][flwr][DEBUG] - ChannelConnectivity.READY
[32mINFO[0m:     Shutting down
[32mINFO[0m:     Waiting for background tasks to complete. (CTRL+C to force quit)
[32mINFO[0m:     Finished server process [[36m266403[0m]
[31mERROR[0m:    Traceback (most recent call last):
  File "/home/ccl/anaconda3/envs/fedops_hyp/lib/python3.11/asyncio/runners.py", line 190, in run
    return runner.run(main)
           ^^^^^^^^^^^^^^^^
  File "/home/ccl/anaconda3/envs/fedops_hyp/lib/python3.11/asyncio/runners.py", line 118, in run
    return self._loop.run_until_complete(task)
           ^^^^^^^^^^^^^^^^^^^^^^^^^^^^^^^^^^^
  File "uvloop/loop.pyx", line 1512, in uvloop.loop.Loop.run_until_complete
  File "uvloop/loop.pyx", line 1505, in uvloop.loop.Loop.run_until_complete
  File "uvloop/loop.pyx", line 1379, in uvloop.loop.Loop.run_forever
  File "uvloop/loop.pyx", line 557, in uvloop.loop.Loop._run
  File "uvloop/loop.pyx", line 476, in uvloop.loop.Loop._on_idle
  File "uvloop/cbhandles.pyx", line 83, in uvloop.loop.Handle._run
  File "uvloop/cbhandles.pyx", line 63, in uvloop.loop.Handle._run
  File "/home/ccl/anaconda3/envs/fedops_hyp/lib/python3.11/site-packages/uvicorn/server.py", line 69, in serve
    with self.capture_signals():
  File "/home/ccl/anaconda3/envs/fedops_hyp/lib/python3.11/contextlib.py", line 144, in __exit__
    next(self.gen)
  File "/home/ccl/anaconda3/envs/fedops_hyp/lib/python3.11/site-packages/uvicorn/server.py", line 330, in capture_signals
    signal.raise_signal(captured_signal)
  File "/home/ccl/anaconda3/envs/fedops_hyp/lib/python3.11/asyncio/runners.py", line 157, in _on_sigint
    raise KeyboardInterrupt()
KeyboardInterrupt

During handling of the above exception, another exception occurred:

Traceback (most recent call last):
  File "/home/ccl/anaconda3/envs/fedops_hyp/lib/python3.11/site-packages/starlette/routing.py", line 699, in lifespan
    await receive()
  File "/home/ccl/anaconda3/envs/fedops_hyp/lib/python3.11/site-packages/uvicorn/lifespan/on.py", line 137, in receive
    return await self.receive_queue.get()
           ^^^^^^^^^^^^^^^^^^^^^^^^^^^^^^
  File "/home/ccl/anaconda3/envs/fedops_hyp/lib/python3.11/asyncio/queues.py", line 158, in get
    await getter
asyncio.exceptions.CancelledError

[31mERROR[0m:    Exception in ASGI application
Traceback (most recent call last):
  File "/home/ccl/anaconda3/envs/fedops_hyp/lib/python3.11/asyncio/runners.py", line 190, in run
    return runner.run(main)
           ^^^^^^^^^^^^^^^^
  File "/home/ccl/anaconda3/envs/fedops_hyp/lib/python3.11/asyncio/runners.py", line 118, in run
    return self._loop.run_until_complete(task)
           ^^^^^^^^^^^^^^^^^^^^^^^^^^^^^^^^^^^
  File "uvloop/loop.pyx", line 1512, in uvloop.loop.Loop.run_until_complete
  File "uvloop/loop.pyx", line 1505, in uvloop.loop.Loop.run_until_complete
  File "uvloop/loop.pyx", line 1379, in uvloop.loop.Loop.run_forever
  File "uvloop/loop.pyx", line 557, in uvloop.loop.Loop._run
  File "uvloop/loop.pyx", line 476, in uvloop.loop.Loop._on_idle
  File "uvloop/cbhandles.pyx", line 83, in uvloop.loop.Handle._run
  File "uvloop/cbhandles.pyx", line 63, in uvloop.loop.Handle._run
  File "/home/ccl/anaconda3/envs/fedops_hyp/lib/python3.11/site-packages/uvicorn/server.py", line 69, in serve
    with self.capture_signals():
  File "/home/ccl/anaconda3/envs/fedops_hyp/lib/python3.11/contextlib.py", line 144, in __exit__
    next(self.gen)
  File "/home/ccl/anaconda3/envs/fedops_hyp/lib/python3.11/site-packages/uvicorn/server.py", line 330, in capture_signals
    signal.raise_signal(captured_signal)
  File "/home/ccl/anaconda3/envs/fedops_hyp/lib/python3.11/asyncio/runners.py", line 157, in _on_sigint
    raise KeyboardInterrupt()
KeyboardInterrupt

During handling of the above exception, another exception occurred:

Traceback (most recent call last):
  File "/home/ccl/anaconda3/envs/fedops_hyp/lib/python3.11/site-packages/uvicorn/protocols/http/httptools_impl.py", line 409, in run_asgi
    result = await app(  # type: ignore[func-returns-value]
             ^^^^^^^^^^^^^^^^^^^^^^^^^^^^^^^^^^^^^^^^^^^^^^
  File "/home/ccl/anaconda3/envs/fedops_hyp/lib/python3.11/site-packages/uvicorn/middleware/proxy_headers.py", line 60, in __call__
    return await self.app(scope, receive, send)
           ^^^^^^^^^^^^^^^^^^^^^^^^^^^^^^^^^^^^
  File "/home/ccl/anaconda3/envs/fedops_hyp/lib/python3.11/site-packages/fastapi/applications.py", line 1054, in __call__
    await super().__call__(scope, receive, send)
  File "/home/ccl/anaconda3/envs/fedops_hyp/lib/python3.11/site-packages/starlette/applications.py", line 112, in __call__
    await self.middleware_stack(scope, receive, send)
  File "/home/ccl/anaconda3/envs/fedops_hyp/lib/python3.11/site-packages/starlette/middleware/errors.py", line 165, in __call__
    await self.app(scope, receive, _send)
  File "/home/ccl/anaconda3/envs/fedops_hyp/lib/python3.11/site-packages/starlette/middleware/exceptions.py", line 62, in __call__
    await wrap_app_handling_exceptions(self.app, conn)(scope, receive, send)
  File "/home/ccl/anaconda3/envs/fedops_hyp/lib/python3.11/site-packages/starlette/_exception_handler.py", line 42, in wrapped_app
    await app(scope, receive, sender)
  File "/home/ccl/anaconda3/envs/fedops_hyp/lib/python3.11/site-packages/starlette/routing.py", line 714, in __call__
    await self.middleware_stack(scope, receive, send)
  File "/home/ccl/anaconda3/envs/fedops_hyp/lib/python3.11/site-packages/starlette/routing.py", line 734, in app
    await route.handle(scope, receive, send)
  File "/home/ccl/anaconda3/envs/fedops_hyp/lib/python3.11/site-packages/starlette/routing.py", line 288, in handle
    await self.app(scope, receive, send)
  File "/home/ccl/anaconda3/envs/fedops_hyp/lib/python3.11/site-packages/starlette/routing.py", line 76, in app
    await wrap_app_handling_exceptions(app, request)(scope, receive, send)
  File "/home/ccl/anaconda3/envs/fedops_hyp/lib/python3.11/site-packages/starlette/_exception_handler.py", line 42, in wrapped_app
    await app(scope, receive, sender)
  File "/home/ccl/anaconda3/envs/fedops_hyp/lib/python3.11/site-packages/starlette/routing.py", line 74, in app
    await response(scope, receive, send)
  File "/home/ccl/anaconda3/envs/fedops_hyp/lib/python3.11/site-packages/starlette/responses.py", line 160, in __call__
    await self.background()
  File "/home/ccl/anaconda3/envs/fedops_hyp/lib/python3.11/site-packages/starlette/background.py", line 41, in __call__
    await task()
  File "/home/ccl/anaconda3/envs/fedops_hyp/lib/python3.11/site-packages/starlette/background.py", line 26, in __call__
    await self.func(*self.args, **self.kwargs)
  File "/home/ccl/safer/FedOps/MNIST/app.py", line 155, in fl_client_start
    await loop.run_in_executor(None, client_start)
asyncio.exceptions.CancelledError
[2025-04-10 14:13:19,827][root][INFO] - ccl-e-server;b0:7b:25:0e:e7:96-client close
Exception ignored in: Exception in thread <module 'threading' from '/home/ccl/anaconda3/envs/fedops_hyp/lib/python3.11/threading.py'>Thread-8 (_do_shutdown)
:
Traceback (most recent call last):
  File "/home/ccl/anaconda3/envs/fedops_hyp/lib/python3.11/threading.py", line 1553, in _shutdown
Traceback (most recent call last):
    atexit_call()  File "uvloop/loop.pyx", line 3254, in uvloop.loop.Loop._do_shutdown

  File "/home/ccl/anaconda3/envs/fedops_hyp/lib/python3.11/concurrent/futures/thread.py", line 31, in _python_exit
    t.join()
  File "uvloop/loop.pyx", line 1290, in uvloop.loop.Loop.call_soon_threadsafe
  File "/home/ccl/anaconda3/envs/fedops_hyp/lib/python3.11/threading.py", line 1112, in join
      File "uvloop/loop.pyx", line 673, in uvloop.loop.Loop._append_ready_handle
self._wait_for_tstate_lock()
  File "/home/ccl/anaconda3/envs/fedops_hyp/lib/python3.11/threading.py", line 1132, in _wait_for_tstate_lock
      File "uvloop/loop.pyx", line 705, in uvloop.loop.Loop._check_closed
if lock.acquire(block, timeout):
   RuntimeError :  Event loop is closed
 ^
^^During handling of the above exception, another exception occurred:
^^
^^Traceback (most recent call last):
^^  File "/home/ccl/anaconda3/envs/fedops_hyp/lib/python3.11/threading.py", line 1038, in _bootstrap_inner
^^^^    ^self.run()^
^^  File "/home/ccl/anaconda3/envs/fedops_hyp/lib/python3.11/threading.py", line 975, in run
^^^    ^self._target(*self._args, **self._kwargs)^
^^  File "uvloop/loop.pyx", line 3256, in uvloop.loop.Loop._do_shutdown
^^^^
KeyboardInterrupt  File "uvloop/loop.pyx", line 1290, in uvloop.loop.Loop.call_soon_threadsafe
:
  File "uvloop/loop.pyx", line 673, in uvloop.loop.Loop._append_ready_handle
  File "uvloop/loop.pyx", line 705, in uvloop.loop.Loop._check_closed
RuntimeError: Event loop is closed
