[93mWARNING [0m:   DEPRECATED FEATURE: flwr.client.start_numpy_client() is deprecated.
	Instead, use `flwr.client.start_client()` by ensuring you first call the `.to_client()` method as shown below:
	flwr.client.start_client(
		server_address='<IP>:<PORT>',
		client=FlowerClient().to_client(), # <-- where FlowerClient is of type flwr.client.NumPyClient object
	)
	Using `start_numpy_client()` is deprecated.

            This is a deprecated feature. It will be removed
            entirely in future versions of Flower.

[2025-04-11 02:14:02,843][flwr][WARNING] - DEPRECATED FEATURE: flwr.client.start_numpy_client() is deprecated.
	Instead, use `flwr.client.start_client()` by ensuring you first call the `.to_client()` method as shown below:
	flwr.client.start_client(
		server_address='<IP>:<PORT>',
		client=FlowerClient().to_client(), # <-- where FlowerClient is of type flwr.client.NumPyClient object
	)
	Using `start_numpy_client()` is deprecated.

            This is a deprecated feature. It will be removed
            entirely in future versions of Flower.

[93mWARNING [0m:   DEPRECATED FEATURE: flwr.client.start_client() is deprecated.
	Instead, use the `flower-supernode` CLI command to start a SuperNode as shown below:

		$ flower-supernode --insecure --superlink='<IP>:<PORT>'

	To view all available options, run:

		$ flower-supernode --help

	Using `start_client()` is deprecated.

            This is a deprecated feature. It will be removed
            entirely in future versions of Flower.

[2025-04-11 02:14:02,845][flwr][WARNING] - DEPRECATED FEATURE: flwr.client.start_client() is deprecated.
	Instead, use the `flower-supernode` CLI command to start a SuperNode as shown below:

		$ flower-supernode --insecure --superlink='<IP>:<PORT>'

	To view all available options, run:

		$ flower-supernode --help

	Using `start_client()` is deprecated.

            This is a deprecated feature. It will be removed
            entirely in future versions of Flower.

[2025-04-11 02:14:02,858][flwr][DEBUG] - Opened insecure gRPC connection (no certificates were passed)
[2025-04-11 02:14:02,862][flwr][DEBUG] - ChannelConnectivity.IDLE
[2025-04-11 02:14:02,863][flwr][DEBUG] - ChannelConnectivity.CONNECTING
[2025-04-11 02:14:02,868][flwr][DEBUG] - ChannelConnectivity.TRANSIENT_FAILURE
[2025-04-11 02:14:03,071][flwr][DEBUG] - gRPC channel closed
--- Logging error ---
Traceback (most recent call last):
  File "/home/ccl/safer/FedOps/MNIST/app.py", line 157, in fl_client_start
    await loop.run_in_executor(None, client_start)
  File "/home/ccl/anaconda3/envs/fedops_hyp/lib/python3.11/concurrent/futures/thread.py", line 58, in run
    result = self.fn(*self.args, **self.kwargs)
             ^^^^^^^^^^^^^^^^^^^^^^^^^^^^^^^^^^
  File "/home/ccl/anaconda3/envs/fedops_hyp/lib/python3.11/site-packages/flwr/client/app.py", line 731, in start_numpy_client
    start_client(
  File "/home/ccl/anaconda3/envs/fedops_hyp/lib/python3.11/site-packages/flwr/client/app.py", line 201, in start_client
    start_client_internal(
  File "/home/ccl/anaconda3/envs/fedops_hyp/lib/python3.11/site-packages/flwr/client/app.py", line 438, in start_client_internal
    message = receive()
              ^^^^^^^^^
  File "/home/ccl/anaconda3/envs/fedops_hyp/lib/python3.11/site-packages/flwr/client/grpc_client/connection.py", line 142, in receive
    proto = next(server_message_iterator)
            ^^^^^^^^^^^^^^^^^^^^^^^^^^^^^
  File "/home/ccl/anaconda3/envs/fedops_hyp/lib/python3.11/site-packages/grpc/_channel.py", line 543, in __next__
    return self._next()
           ^^^^^^^^^^^^
  File "/home/ccl/anaconda3/envs/fedops_hyp/lib/python3.11/site-packages/grpc/_channel.py", line 969, in _next
    raise self
grpc._channel._MultiThreadedRendezvous: <_MultiThreadedRendezvous of RPC that terminated with:
	status = StatusCode.UNAVAILABLE
	details = "failed to connect to all addresses; last error: UNAVAILABLE: ipv4:192.9.201.228:40025: Socket closed"
	debug_error_string = "UNKNOWN:Error received from peer  {grpc_message:"failed to connect to all addresses; last error: UNAVAILABLE: ipv4:192.9.201.228:40025: Socket closed", grpc_status:14, created_time:"2025-04-11T02:14:02.868434434+09:00"}"
>

During handling of the above exception, another exception occurred:

Traceback (most recent call last):
  File "/home/ccl/anaconda3/envs/fedops_hyp/lib/python3.11/logging/__init__.py", line 1110, in emit
    msg = self.format(record)
          ^^^^^^^^^^^^^^^^^^^
  File "/home/ccl/anaconda3/envs/fedops_hyp/lib/python3.11/logging/__init__.py", line 953, in format
    return fmt.format(record)
           ^^^^^^^^^^^^^^^^^^
  File "/home/ccl/anaconda3/envs/fedops_hyp/lib/python3.11/logging/__init__.py", line 687, in format
    record.message = record.getMessage()
                     ^^^^^^^^^^^^^^^^^^^
  File "/home/ccl/anaconda3/envs/fedops_hyp/lib/python3.11/logging/__init__.py", line 377, in getMessage
    msg = msg % self.args
          ~~~~^~~~~~~~~~~
TypeError: not all arguments converted during string formatting
Call stack:
  File "/home/ccl/safer/FedOps/MNIST/client_main.py", line 82, in <module>
    main()
  File "/home/ccl/anaconda3/envs/fedops_hyp/lib/python3.11/site-packages/hydra/main.py", line 94, in decorated_main
    _run_hydra(
  File "/home/ccl/anaconda3/envs/fedops_hyp/lib/python3.11/site-packages/hydra/_internal/utils.py", line 394, in _run_hydra
    _run_app(
  File "/home/ccl/anaconda3/envs/fedops_hyp/lib/python3.11/site-packages/hydra/_internal/utils.py", line 457, in _run_app
    run_and_report(
  File "/home/ccl/anaconda3/envs/fedops_hyp/lib/python3.11/site-packages/hydra/_internal/utils.py", line 220, in run_and_report
    return func()
  File "/home/ccl/anaconda3/envs/fedops_hyp/lib/python3.11/site-packages/hydra/_internal/utils.py", line 458, in <lambda>
    lambda: hydra.run(
  File "/home/ccl/anaconda3/envs/fedops_hyp/lib/python3.11/site-packages/hydra/_internal/hydra.py", line 119, in run
    ret = run_job(
  File "/home/ccl/anaconda3/envs/fedops_hyp/lib/python3.11/site-packages/hydra/core/utils.py", line 186, in run_job
    ret.return_value = task_function(task_cfg)
  File "/home/ccl/safer/FedOps/MNIST/client_main.py", line 78, in main
    fl_client.start()
  File "/home/ccl/safer/FedOps/MNIST/app.py", line 239, in start
    uvicorn.run(self.app, host='0.0.0.0', port=self.client_port)
  File "/home/ccl/anaconda3/envs/fedops_hyp/lib/python3.11/site-packages/uvicorn/main.py", line 579, in run
    server.run()
  File "/home/ccl/anaconda3/envs/fedops_hyp/lib/python3.11/site-packages/uvicorn/server.py", line 66, in run
    return asyncio.run(self.serve(sockets=sockets))
  File "/home/ccl/anaconda3/envs/fedops_hyp/lib/python3.11/asyncio/runners.py", line 190, in run
    return runner.run(main)
  File "/home/ccl/anaconda3/envs/fedops_hyp/lib/python3.11/asyncio/runners.py", line 118, in run
    return self._loop.run_until_complete(task)
  File "/home/ccl/anaconda3/envs/fedops_hyp/lib/python3.11/site-packages/uvicorn/protocols/http/httptools_impl.py", line 409, in run_asgi
    result = await app(  # type: ignore[func-returns-value]
  File "/home/ccl/anaconda3/envs/fedops_hyp/lib/python3.11/site-packages/uvicorn/middleware/proxy_headers.py", line 60, in __call__
    return await self.app(scope, receive, send)
  File "/home/ccl/anaconda3/envs/fedops_hyp/lib/python3.11/site-packages/fastapi/applications.py", line 1054, in __call__
    await super().__call__(scope, receive, send)
  File "/home/ccl/anaconda3/envs/fedops_hyp/lib/python3.11/site-packages/starlette/applications.py", line 112, in __call__
    await self.middleware_stack(scope, receive, send)
  File "/home/ccl/anaconda3/envs/fedops_hyp/lib/python3.11/site-packages/starlette/middleware/errors.py", line 165, in __call__
    await self.app(scope, receive, _send)
  File "/home/ccl/anaconda3/envs/fedops_hyp/lib/python3.11/site-packages/starlette/middleware/exceptions.py", line 62, in __call__
    await wrap_app_handling_exceptions(self.app, conn)(scope, receive, send)
  File "/home/ccl/anaconda3/envs/fedops_hyp/lib/python3.11/site-packages/starlette/_exception_handler.py", line 42, in wrapped_app
    await app(scope, receive, sender)
  File "/home/ccl/anaconda3/envs/fedops_hyp/lib/python3.11/site-packages/starlette/routing.py", line 714, in __call__
    await self.middleware_stack(scope, receive, send)
  File "/home/ccl/anaconda3/envs/fedops_hyp/lib/python3.11/site-packages/starlette/routing.py", line 734, in app
    await route.handle(scope, receive, send)
  File "/home/ccl/anaconda3/envs/fedops_hyp/lib/python3.11/site-packages/starlette/routing.py", line 288, in handle
    await self.app(scope, receive, send)
  File "/home/ccl/anaconda3/envs/fedops_hyp/lib/python3.11/site-packages/starlette/routing.py", line 76, in app
    await wrap_app_handling_exceptions(app, request)(scope, receive, send)
  File "/home/ccl/anaconda3/envs/fedops_hyp/lib/python3.11/site-packages/starlette/_exception_handler.py", line 42, in wrapped_app
    await app(scope, receive, sender)
  File "/home/ccl/anaconda3/envs/fedops_hyp/lib/python3.11/site-packages/starlette/routing.py", line 74, in app
    await response(scope, receive, send)
  File "/home/ccl/anaconda3/envs/fedops_hyp/lib/python3.11/site-packages/starlette/responses.py", line 160, in __call__
    await self.background()
  File "/home/ccl/anaconda3/envs/fedops_hyp/lib/python3.11/site-packages/starlette/background.py", line 41, in __call__
    await task()
  File "/home/ccl/anaconda3/envs/fedops_hyp/lib/python3.11/site-packages/starlette/background.py", line 26, in __call__
    await self.func(*self.args, **self.kwargs)
  File "/home/ccl/safer/FedOps/MNIST/app.py", line 196, in fl_client_start
    logging.info('[E][PC0002] learning', e)
Message: '[E][PC0002] learning'
Arguments: (<_MultiThreadedRendezvous of RPC that terminated with:
	status = StatusCode.UNAVAILABLE
	details = "failed to connect to all addresses; last error: UNAVAILABLE: ipv4:192.9.201.228:40025: Socket closed"
	debug_error_string = "UNKNOWN:Error received from peer  {grpc_message:"failed to connect to all addresses; last error: UNAVAILABLE: ipv4:192.9.201.228:40025: Socket closed", grpc_status:14, created_time:"2025-04-11T02:14:02.868434434+09:00"}"
>,)
--- Logging error ---
Traceback (most recent call last):
  File "/home/ccl/safer/FedOps/MNIST/app.py", line 157, in fl_client_start
    await loop.run_in_executor(None, client_start)
  File "/home/ccl/anaconda3/envs/fedops_hyp/lib/python3.11/concurrent/futures/thread.py", line 58, in run
    result = self.fn(*self.args, **self.kwargs)
             ^^^^^^^^^^^^^^^^^^^^^^^^^^^^^^^^^^
  File "/home/ccl/anaconda3/envs/fedops_hyp/lib/python3.11/site-packages/flwr/client/app.py", line 731, in start_numpy_client
    start_client(
  File "/home/ccl/anaconda3/envs/fedops_hyp/lib/python3.11/site-packages/flwr/client/app.py", line 201, in start_client
    start_client_internal(
  File "/home/ccl/anaconda3/envs/fedops_hyp/lib/python3.11/site-packages/flwr/client/app.py", line 438, in start_client_internal
    message = receive()
              ^^^^^^^^^
  File "/home/ccl/anaconda3/envs/fedops_hyp/lib/python3.11/site-packages/flwr/client/grpc_client/connection.py", line 142, in receive
    proto = next(server_message_iterator)
            ^^^^^^^^^^^^^^^^^^^^^^^^^^^^^
  File "/home/ccl/anaconda3/envs/fedops_hyp/lib/python3.11/site-packages/grpc/_channel.py", line 543, in __next__
    return self._next()
           ^^^^^^^^^^^^
  File "/home/ccl/anaconda3/envs/fedops_hyp/lib/python3.11/site-packages/grpc/_channel.py", line 969, in _next
    raise self
grpc._channel._MultiThreadedRendezvous: <_MultiThreadedRendezvous of RPC that terminated with:
	status = StatusCode.UNAVAILABLE
	details = "failed to connect to all addresses; last error: UNAVAILABLE: ipv4:192.9.201.228:40025: Socket closed"
	debug_error_string = "UNKNOWN:Error received from peer  {grpc_message:"failed to connect to all addresses; last error: UNAVAILABLE: ipv4:192.9.201.228:40025: Socket closed", grpc_status:14, created_time:"2025-04-11T02:14:02.868434434+09:00"}"
>

During handling of the above exception, another exception occurred:

Traceback (most recent call last):
  File "/home/ccl/anaconda3/envs/fedops_hyp/lib/python3.11/logging/__init__.py", line 1110, in emit
    msg = self.format(record)
          ^^^^^^^^^^^^^^^^^^^
  File "/home/ccl/anaconda3/envs/fedops_hyp/lib/python3.11/logging/__init__.py", line 953, in format
    return fmt.format(record)
           ^^^^^^^^^^^^^^^^^^
  File "/home/ccl/anaconda3/envs/fedops_hyp/lib/python3.11/logging/__init__.py", line 687, in format
    record.message = record.getMessage()
                     ^^^^^^^^^^^^^^^^^^^
  File "/home/ccl/anaconda3/envs/fedops_hyp/lib/python3.11/logging/__init__.py", line 377, in getMessage
    msg = msg % self.args
          ~~~~^~~~~~~~~~~
TypeError: not all arguments converted during string formatting
Call stack:
  File "/home/ccl/safer/FedOps/MNIST/client_main.py", line 82, in <module>
    main()
  File "/home/ccl/anaconda3/envs/fedops_hyp/lib/python3.11/site-packages/hydra/main.py", line 94, in decorated_main
    _run_hydra(
  File "/home/ccl/anaconda3/envs/fedops_hyp/lib/python3.11/site-packages/hydra/_internal/utils.py", line 394, in _run_hydra
    _run_app(
  File "/home/ccl/anaconda3/envs/fedops_hyp/lib/python3.11/site-packages/hydra/_internal/utils.py", line 457, in _run_app
    run_and_report(
  File "/home/ccl/anaconda3/envs/fedops_hyp/lib/python3.11/site-packages/hydra/_internal/utils.py", line 220, in run_and_report
    return func()
  File "/home/ccl/anaconda3/envs/fedops_hyp/lib/python3.11/site-packages/hydra/_internal/utils.py", line 458, in <lambda>
    lambda: hydra.run(
  File "/home/ccl/anaconda3/envs/fedops_hyp/lib/python3.11/site-packages/hydra/_internal/hydra.py", line 119, in run
    ret = run_job(
  File "/home/ccl/anaconda3/envs/fedops_hyp/lib/python3.11/site-packages/hydra/core/utils.py", line 186, in run_job
    ret.return_value = task_function(task_cfg)
  File "/home/ccl/safer/FedOps/MNIST/client_main.py", line 78, in main
    fl_client.start()
  File "/home/ccl/safer/FedOps/MNIST/app.py", line 239, in start
    uvicorn.run(self.app, host='0.0.0.0', port=self.client_port)
  File "/home/ccl/anaconda3/envs/fedops_hyp/lib/python3.11/site-packages/uvicorn/main.py", line 579, in run
    server.run()
  File "/home/ccl/anaconda3/envs/fedops_hyp/lib/python3.11/site-packages/uvicorn/server.py", line 66, in run
    return asyncio.run(self.serve(sockets=sockets))
  File "/home/ccl/anaconda3/envs/fedops_hyp/lib/python3.11/asyncio/runners.py", line 190, in run
    return runner.run(main)
  File "/home/ccl/anaconda3/envs/fedops_hyp/lib/python3.11/asyncio/runners.py", line 118, in run
    return self._loop.run_until_complete(task)
  File "/home/ccl/anaconda3/envs/fedops_hyp/lib/python3.11/site-packages/uvicorn/protocols/http/httptools_impl.py", line 409, in run_asgi
    result = await app(  # type: ignore[func-returns-value]
  File "/home/ccl/anaconda3/envs/fedops_hyp/lib/python3.11/site-packages/uvicorn/middleware/proxy_headers.py", line 60, in __call__
    return await self.app(scope, receive, send)
  File "/home/ccl/anaconda3/envs/fedops_hyp/lib/python3.11/site-packages/fastapi/applications.py", line 1054, in __call__
    await super().__call__(scope, receive, send)
  File "/home/ccl/anaconda3/envs/fedops_hyp/lib/python3.11/site-packages/starlette/applications.py", line 112, in __call__
    await self.middleware_stack(scope, receive, send)
  File "/home/ccl/anaconda3/envs/fedops_hyp/lib/python3.11/site-packages/starlette/middleware/errors.py", line 165, in __call__
    await self.app(scope, receive, _send)
  File "/home/ccl/anaconda3/envs/fedops_hyp/lib/python3.11/site-packages/starlette/middleware/exceptions.py", line 62, in __call__
    await wrap_app_handling_exceptions(self.app, conn)(scope, receive, send)
  File "/home/ccl/anaconda3/envs/fedops_hyp/lib/python3.11/site-packages/starlette/_exception_handler.py", line 42, in wrapped_app
    await app(scope, receive, sender)
  File "/home/ccl/anaconda3/envs/fedops_hyp/lib/python3.11/site-packages/starlette/routing.py", line 714, in __call__
    await self.middleware_stack(scope, receive, send)
  File "/home/ccl/anaconda3/envs/fedops_hyp/lib/python3.11/site-packages/starlette/routing.py", line 734, in app
    await route.handle(scope, receive, send)
  File "/home/ccl/anaconda3/envs/fedops_hyp/lib/python3.11/site-packages/starlette/routing.py", line 288, in handle
    await self.app(scope, receive, send)
  File "/home/ccl/anaconda3/envs/fedops_hyp/lib/python3.11/site-packages/starlette/routing.py", line 76, in app
    await wrap_app_handling_exceptions(app, request)(scope, receive, send)
  File "/home/ccl/anaconda3/envs/fedops_hyp/lib/python3.11/site-packages/starlette/_exception_handler.py", line 42, in wrapped_app
    await app(scope, receive, sender)
  File "/home/ccl/anaconda3/envs/fedops_hyp/lib/python3.11/site-packages/starlette/routing.py", line 74, in app
    await response(scope, receive, send)
  File "/home/ccl/anaconda3/envs/fedops_hyp/lib/python3.11/site-packages/starlette/responses.py", line 160, in __call__
    await self.background()
  File "/home/ccl/anaconda3/envs/fedops_hyp/lib/python3.11/site-packages/starlette/background.py", line 41, in __call__
    await task()
  File "/home/ccl/anaconda3/envs/fedops_hyp/lib/python3.11/site-packages/starlette/background.py", line 26, in __call__
    await self.func(*self.args, **self.kwargs)
  File "/home/ccl/safer/FedOps/MNIST/app.py", line 196, in fl_client_start
    logging.info('[E][PC0002] learning', e)
Message: '[E][PC0002] learning'
Arguments: (<_MultiThreadedRendezvous of RPC that terminated with:
	status = StatusCode.UNAVAILABLE
	details = "failed to connect to all addresses; last error: UNAVAILABLE: ipv4:192.9.201.228:40025: Socket closed"
	debug_error_string = "UNKNOWN:Error received from peer  {grpc_message:"failed to connect to all addresses; last error: UNAVAILABLE: ipv4:192.9.201.228:40025: Socket closed", grpc_status:14, created_time:"2025-04-11T02:14:02.868434434+09:00"}"
>,)
[2025-04-11 02:14:03,097][root][INFO] - notify_fail start
[2025-04-11 02:14:03,115][root][ERROR] - trainFin
[31mERROR[0m:    Exception in ASGI application
Traceback (most recent call last):
  File "/home/ccl/anaconda3/envs/fedops_hyp/lib/python3.11/site-packages/uvicorn/protocols/http/httptools_impl.py", line 409, in run_asgi
    result = await app(  # type: ignore[func-returns-value]
             ^^^^^^^^^^^^^^^^^^^^^^^^^^^^^^^^^^^^^^^^^^^^^^
  File "/home/ccl/anaconda3/envs/fedops_hyp/lib/python3.11/site-packages/uvicorn/middleware/proxy_headers.py", line 60, in __call__
    return await self.app(scope, receive, send)
           ^^^^^^^^^^^^^^^^^^^^^^^^^^^^^^^^^^^^
  File "/home/ccl/anaconda3/envs/fedops_hyp/lib/python3.11/site-packages/fastapi/applications.py", line 1054, in __call__
    await super().__call__(scope, receive, send)
  File "/home/ccl/anaconda3/envs/fedops_hyp/lib/python3.11/site-packages/starlette/applications.py", line 112, in __call__
    await self.middleware_stack(scope, receive, send)
  File "/home/ccl/anaconda3/envs/fedops_hyp/lib/python3.11/site-packages/starlette/middleware/errors.py", line 187, in __call__
    raise exc
  File "/home/ccl/anaconda3/envs/fedops_hyp/lib/python3.11/site-packages/starlette/middleware/errors.py", line 165, in __call__
    await self.app(scope, receive, _send)
  File "/home/ccl/anaconda3/envs/fedops_hyp/lib/python3.11/site-packages/starlette/middleware/exceptions.py", line 62, in __call__
    await wrap_app_handling_exceptions(self.app, conn)(scope, receive, send)
  File "/home/ccl/anaconda3/envs/fedops_hyp/lib/python3.11/site-packages/starlette/_exception_handler.py", line 53, in wrapped_app
    raise exc
  File "/home/ccl/anaconda3/envs/fedops_hyp/lib/python3.11/site-packages/starlette/_exception_handler.py", line 42, in wrapped_app
    await app(scope, receive, sender)
  File "/home/ccl/anaconda3/envs/fedops_hyp/lib/python3.11/site-packages/starlette/routing.py", line 714, in __call__
    await self.middleware_stack(scope, receive, send)
  File "/home/ccl/anaconda3/envs/fedops_hyp/lib/python3.11/site-packages/starlette/routing.py", line 734, in app
    await route.handle(scope, receive, send)
  File "/home/ccl/anaconda3/envs/fedops_hyp/lib/python3.11/site-packages/starlette/routing.py", line 288, in handle
    await self.app(scope, receive, send)
  File "/home/ccl/anaconda3/envs/fedops_hyp/lib/python3.11/site-packages/starlette/routing.py", line 76, in app
    await wrap_app_handling_exceptions(app, request)(scope, receive, send)
  File "/home/ccl/anaconda3/envs/fedops_hyp/lib/python3.11/site-packages/starlette/_exception_handler.py", line 53, in wrapped_app
    raise exc
  File "/home/ccl/anaconda3/envs/fedops_hyp/lib/python3.11/site-packages/starlette/_exception_handler.py", line 42, in wrapped_app
    await app(scope, receive, sender)
  File "/home/ccl/anaconda3/envs/fedops_hyp/lib/python3.11/site-packages/starlette/routing.py", line 74, in app
    await response(scope, receive, send)
  File "/home/ccl/anaconda3/envs/fedops_hyp/lib/python3.11/site-packages/starlette/responses.py", line 160, in __call__
    await self.background()
  File "/home/ccl/anaconda3/envs/fedops_hyp/lib/python3.11/site-packages/starlette/background.py", line 41, in __call__
    await task()
  File "/home/ccl/anaconda3/envs/fedops_hyp/lib/python3.11/site-packages/starlette/background.py", line 26, in __call__
    await self.func(*self.args, **self.kwargs)
  File "/home/ccl/safer/FedOps/MNIST/app.py", line 199, in fl_client_start
    raise e
  File "/home/ccl/safer/FedOps/MNIST/app.py", line 157, in fl_client_start
    await loop.run_in_executor(None, client_start)
  File "/home/ccl/anaconda3/envs/fedops_hyp/lib/python3.11/concurrent/futures/thread.py", line 58, in run
    result = self.fn(*self.args, **self.kwargs)
             ^^^^^^^^^^^^^^^^^^^^^^^^^^^^^^^^^^
  File "/home/ccl/anaconda3/envs/fedops_hyp/lib/python3.11/site-packages/flwr/client/app.py", line 731, in start_numpy_client
    start_client(
  File "/home/ccl/anaconda3/envs/fedops_hyp/lib/python3.11/site-packages/flwr/client/app.py", line 201, in start_client
    start_client_internal(
  File "/home/ccl/anaconda3/envs/fedops_hyp/lib/python3.11/site-packages/flwr/client/app.py", line 438, in start_client_internal
    message = receive()
              ^^^^^^^^^
  File "/home/ccl/anaconda3/envs/fedops_hyp/lib/python3.11/site-packages/flwr/client/grpc_client/connection.py", line 142, in receive
    proto = next(server_message_iterator)
            ^^^^^^^^^^^^^^^^^^^^^^^^^^^^^
  File "/home/ccl/anaconda3/envs/fedops_hyp/lib/python3.11/site-packages/grpc/_channel.py", line 543, in __next__
    return self._next()
           ^^^^^^^^^^^^
  File "/home/ccl/anaconda3/envs/fedops_hyp/lib/python3.11/site-packages/grpc/_channel.py", line 969, in _next
    raise self
grpc._channel._MultiThreadedRendezvous: <_MultiThreadedRendezvous of RPC that terminated with:
	status = StatusCode.UNAVAILABLE
	details = "failed to connect to all addresses; last error: UNAVAILABLE: ipv4:192.9.201.228:40025: Socket closed"
	debug_error_string = "UNKNOWN:Error received from peer  {grpc_message:"failed to connect to all addresses; last error: UNAVAILABLE: ipv4:192.9.201.228:40025: Socket closed", grpc_status:14, created_time:"2025-04-11T02:14:02.868434434+09:00"}"
>
[32mINFO[0m:     127.0.0.1:42284 - "[1mGET /online HTTP/1.1[0m" [32m200 OK[0m
[32mINFO[0m:     127.0.0.1:54400 - "[1mGET /online HTTP/1.1[0m" [32m200 OK[0m
[32mINFO[0m:     127.0.0.1:54402 - "[1mGET /online HTTP/1.1[0m" [32m200 OK[0m
[32mINFO[0m:     127.0.0.1:36846 - "[1mGET /online HTTP/1.1[0m" [32m200 OK[0m
[32mINFO[0m:     127.0.0.1:40120 - "[1mGET /online HTTP/1.1[0m" [32m200 OK[0m
[32mINFO[0m:     127.0.0.1:40136 - "[1mGET /online HTTP/1.1[0m" [32m200 OK[0m
[32mINFO[0m:     127.0.0.1:37630 - "[1mGET /online HTTP/1.1[0m" [32m200 OK[0m
[32mINFO[0m:     127.0.0.1:55034 - "[1mGET /online HTTP/1.1[0m" [32m200 OK[0m
[32mINFO[0m:     127.0.0.1:55046 - "[1mGET /online HTTP/1.1[0m" [32m200 OK[0m
[32mINFO[0m:     127.0.0.1:52654 - "[1mGET /online HTTP/1.1[0m" [32m200 OK[0m
[32mINFO[0m:     127.0.0.1:39498 - "[1mGET /online HTTP/1.1[0m" [32m200 OK[0m
[32mINFO[0m:     127.0.0.1:39504 - "[1mGET /online HTTP/1.1[0m" [32m200 OK[0m
[32mINFO[0m:     127.0.0.1:36924 - "[1mGET /online HTTP/1.1[0m" [32m200 OK[0m
[32mINFO[0m:     127.0.0.1:44572 - "[1mGET /online HTTP/1.1[0m" [32m200 OK[0m
[32mINFO[0m:     127.0.0.1:44580 - "[1mGET /online HTTP/1.1[0m" [32m200 OK[0m
[32mINFO[0m:     127.0.0.1:53812 - "[1mGET /online HTTP/1.1[0m" [32m200 OK[0m
[32mINFO[0m:     127.0.0.1:38684 - "[1mGET /online HTTP/1.1[0m" [32m200 OK[0m
[2025-04-11 02:15:53,907][root][INFO] - bulid model
[2025-04-11 02:15:53,908][root][INFO] - FL start
Response: {"task_id":"mnist","port":40025}
Response JSON: {'task_id': 'mnist', 'port': 40025}
[2025-04-11 02:15:53,922][client_api][INFO] - FL_server_IP:port - ccl.gachon.ac.kr:40025
[32mINFO[0m:     127.0.0.1:38690 - "[1mPOST /start HTTP/1.1[0m" [32m200 OK[0m
[2025-04-11 02:15:53,923][root][INFO] - FL learning ready
[2025-04-11 02:15:53,924][root][INFO] - fl_task_id: mnist
[2025-04-11 02:15:53,924][root][INFO] - dataset: MNIST
[2025-04-11 02:15:53,924][root][INFO] - output_size: 10
[2025-04-11 02:15:53,925][root][INFO] - validation_split: 0.2
[2025-04-11 02:15:53,925][root][INFO] - model_type: hyperparameter
[2025-04-11 02:15:53,925][root][INFO] - wandb_key: 38f6cf3c2c37660d42ebfe8ab434b72d34be3b31
[2025-04-11 02:15:53,925][root][INFO] - wandb_account: rirakang@gachon.ac.kr
[34m[1mwandb[0m: [33mWARNING[0m Calling wandb.login() after wandb.init() has no effect.
[93mWARNING [0m:   DEPRECATED FEATURE: flwr.client.start_numpy_client() is deprecated.
	Instead, use `flwr.client.start_client()` by ensuring you first call the `.to_client()` method as shown below:
	flwr.client.start_client(
		server_address='<IP>:<PORT>',
		client=FlowerClient().to_client(), # <-- where FlowerClient is of type flwr.client.NumPyClient object
	)
	Using `start_numpy_client()` is deprecated.

            This is a deprecated feature. It will be removed
            entirely in future versions of Flower.

[2025-04-11 02:15:53,932][flwr][WARNING] - DEPRECATED FEATURE: flwr.client.start_numpy_client() is deprecated.
	Instead, use `flwr.client.start_client()` by ensuring you first call the `.to_client()` method as shown below:
	flwr.client.start_client(
		server_address='<IP>:<PORT>',
		client=FlowerClient().to_client(), # <-- where FlowerClient is of type flwr.client.NumPyClient object
	)
	Using `start_numpy_client()` is deprecated.

            This is a deprecated feature. It will be removed
            entirely in future versions of Flower.

[93mWARNING [0m:   DEPRECATED FEATURE: flwr.client.start_client() is deprecated.
	Instead, use the `flower-supernode` CLI command to start a SuperNode as shown below:

		$ flower-supernode --insecure --superlink='<IP>:<PORT>'

	To view all available options, run:

		$ flower-supernode --help

	Using `start_client()` is deprecated.

            This is a deprecated feature. It will be removed
            entirely in future versions of Flower.

[2025-04-11 02:15:53,933][flwr][WARNING] - DEPRECATED FEATURE: flwr.client.start_client() is deprecated.
	Instead, use the `flower-supernode` CLI command to start a SuperNode as shown below:

		$ flower-supernode --insecure --superlink='<IP>:<PORT>'

	To view all available options, run:

		$ flower-supernode --help

	Using `start_client()` is deprecated.

            This is a deprecated feature. It will be removed
            entirely in future versions of Flower.

[2025-04-11 02:15:53,935][flwr][DEBUG] - Opened insecure gRPC connection (no certificates were passed)
[2025-04-11 02:15:53,940][flwr][DEBUG] - ChannelConnectivity.IDLE
[2025-04-11 02:15:53,941][flwr][DEBUG] - ChannelConnectivity.CONNECTING
[2025-04-11 02:15:53,945][flwr][DEBUG] - ChannelConnectivity.READY
[32mINFO[0m:     127.0.0.1:55082 - "[1mGET /online HTTP/1.1[0m" [32m200 OK[0m
[32mINFO[0m:     127.0.0.1:48856 - "[1mGET /online HTTP/1.1[0m" [32m200 OK[0m
[32mINFO[0m:     127.0.0.1:49928 - "[1mGET /online HTTP/1.1[0m" [32m200 OK[0m
[32mINFO[0m:     127.0.0.1:33758 - "[1mGET /online HTTP/1.1[0m" [32m200 OK[0m
[32mINFO[0m:     Shutting down
[32mINFO[0m:     Waiting for background tasks to complete. (CTRL+C to force quit)
[32mINFO[0m:     Finished server process [[36m1050480[0m]
[31mERROR[0m:    Exception in ASGI application
Traceback (most recent call last):
  File "/home/ccl/anaconda3/envs/fedops_hyp/lib/python3.11/asyncio/runners.py", line 190, in run
    return runner.run(main)
           ^^^^^^^^^^^^^^^^
  File "/home/ccl/anaconda3/envs/fedops_hyp/lib/python3.11/asyncio/runners.py", line 118, in run
    return self._loop.run_until_complete(task)
           ^^^^^^^^^^^^^^^^^^^^^^^^^^^^^^^^^^^
  File "uvloop/loop.pyx", line 1512, in uvloop.loop.Loop.run_until_complete
  File "uvloop/loop.pyx", line 1505, in uvloop.loop.Loop.run_until_complete
  File "uvloop/loop.pyx", line 1379, in uvloop.loop.Loop.run_forever
  File "uvloop/loop.pyx", line 557, in uvloop.loop.Loop._run
  File "uvloop/loop.pyx", line 476, in uvloop.loop.Loop._on_idle
  File "uvloop/cbhandles.pyx", line 83, in uvloop.loop.Handle._run
  File "uvloop/cbhandles.pyx", line 63, in uvloop.loop.Handle._run
  File "/home/ccl/anaconda3/envs/fedops_hyp/lib/python3.11/site-packages/uvicorn/server.py", line 69, in serve
    with self.capture_signals():
  File "/home/ccl/anaconda3/envs/fedops_hyp/lib/python3.11/contextlib.py", line 144, in __exit__
    next(self.gen)
  File "/home/ccl/anaconda3/envs/fedops_hyp/lib/python3.11/site-packages/uvicorn/server.py", line 330, in capture_signals
    signal.raise_signal(captured_signal)
  File "/home/ccl/anaconda3/envs/fedops_hyp/lib/python3.11/asyncio/runners.py", line 157, in _on_sigint
    raise KeyboardInterrupt()
KeyboardInterrupt

During handling of the above exception, another exception occurred:

Traceback (most recent call last):
  File "/home/ccl/anaconda3/envs/fedops_hyp/lib/python3.11/site-packages/uvicorn/protocols/http/httptools_impl.py", line 409, in run_asgi
    result = await app(  # type: ignore[func-returns-value]
             ^^^^^^^^^^^^^^^^^^^^^^^^^^^^^^^^^^^^^^^^^^^^^^
  File "/home/ccl/anaconda3/envs/fedops_hyp/lib/python3.11/site-packages/uvicorn/middleware/proxy_headers.py", line 60, in __call__
    return await self.app(scope, receive, send)
           ^^^^^^^^^^^^^^^^^^^^^^^^^^^^^^^^^^^^
  File "/home/ccl/anaconda3/envs/fedops_hyp/lib/python3.11/site-packages/fastapi/applications.py", line 1054, in __call__
    await super().__call__(scope, receive, send)
  File "/home/ccl/anaconda3/envs/fedops_hyp/lib/python3.11/site-packages/starlette/applications.py", line 112, in __call__
    await self.middleware_stack(scope, receive, send)
  File "/home/ccl/anaconda3/envs/fedops_hyp/lib/python3.11/site-packages/starlette/middleware/errors.py", line 165, in __call__
    await self.app(scope, receive, _send)
  File "/home/ccl/anaconda3/envs/fedops_hyp/lib/python3.11/site-packages/starlette/middleware/exceptions.py", line 62, in __call__
    await wrap_app_handling_exceptions(self.app, conn)(scope, receive, send)
  File "/home/ccl/anaconda3/envs/fedops_hyp/lib/python3.11/site-packages/starlette/_exception_handler.py", line 42, in wrapped_app
    await app(scope, receive, sender)
  File "/home/ccl/anaconda3/envs/fedops_hyp/lib/python3.11/site-packages/starlette/routing.py", line 714, in __call__
    await self.middleware_stack(scope, receive, send)
  File "/home/ccl/anaconda3/envs/fedops_hyp/lib/python3.11/site-packages/starlette/routing.py", line 734, in app
    await route.handle(scope, receive, send)
  File "/home/ccl/anaconda3/envs/fedops_hyp/lib/python3.11/site-packages/starlette/routing.py", line 288, in handle
    await self.app(scope, receive, send)
  File "/home/ccl/anaconda3/envs/fedops_hyp/lib/python3.11/site-packages/starlette/routing.py", line 76, in app
    await wrap_app_handling_exceptions(app, request)(scope, receive, send)
  File "/home/ccl/anaconda3/envs/fedops_hyp/lib/python3.11/site-packages/starlette/_exception_handler.py", line 42, in wrapped_app
    await app(scope, receive, sender)
  File "/home/ccl/anaconda3/envs/fedops_hyp/lib/python3.11/site-packages/starlette/routing.py", line 74, in app
    await response(scope, receive, send)
  File "/home/ccl/anaconda3/envs/fedops_hyp/lib/python3.11/site-packages/starlette/responses.py", line 160, in __call__
    await self.background()
  File "/home/ccl/anaconda3/envs/fedops_hyp/lib/python3.11/site-packages/starlette/background.py", line 41, in __call__
    await task()
  File "/home/ccl/anaconda3/envs/fedops_hyp/lib/python3.11/site-packages/starlette/background.py", line 26, in __call__
    await self.func(*self.args, **self.kwargs)
  File "/home/ccl/safer/FedOps/MNIST/app.py", line 157, in fl_client_start
    fl_start_time = time.time()
asyncio.exceptions.CancelledError
[31mERROR[0m:    Traceback (most recent call last):
  File "/home/ccl/anaconda3/envs/fedops_hyp/lib/python3.11/asyncio/runners.py", line 190, in run
    return runner.run(main)
           ^^^^^^^^^^^^^^^^
  File "/home/ccl/anaconda3/envs/fedops_hyp/lib/python3.11/asyncio/runners.py", line 118, in run
    return self._loop.run_until_complete(task)
           ^^^^^^^^^^^^^^^^^^^^^^^^^^^^^^^^^^^
  File "uvloop/loop.pyx", line 1512, in uvloop.loop.Loop.run_until_complete
  File "uvloop/loop.pyx", line 1505, in uvloop.loop.Loop.run_until_complete
  File "uvloop/loop.pyx", line 1379, in uvloop.loop.Loop.run_forever
  File "uvloop/loop.pyx", line 557, in uvloop.loop.Loop._run
  File "uvloop/loop.pyx", line 476, in uvloop.loop.Loop._on_idle
  File "uvloop/cbhandles.pyx", line 83, in uvloop.loop.Handle._run
  File "uvloop/cbhandles.pyx", line 63, in uvloop.loop.Handle._run
  File "/home/ccl/anaconda3/envs/fedops_hyp/lib/python3.11/site-packages/uvicorn/server.py", line 69, in serve
    with self.capture_signals():
  File "/home/ccl/anaconda3/envs/fedops_hyp/lib/python3.11/contextlib.py", line 144, in __exit__
    next(self.gen)
  File "/home/ccl/anaconda3/envs/fedops_hyp/lib/python3.11/site-packages/uvicorn/server.py", line 330, in capture_signals
    signal.raise_signal(captured_signal)
  File "/home/ccl/anaconda3/envs/fedops_hyp/lib/python3.11/asyncio/runners.py", line 157, in _on_sigint
    raise KeyboardInterrupt()
KeyboardInterrupt

During handling of the above exception, another exception occurred:

Traceback (most recent call last):
  File "/home/ccl/anaconda3/envs/fedops_hyp/lib/python3.11/site-packages/starlette/routing.py", line 699, in lifespan
    await receive()
  File "/home/ccl/anaconda3/envs/fedops_hyp/lib/python3.11/site-packages/uvicorn/lifespan/on.py", line 137, in receive
    return await self.receive_queue.get()
           ^^^^^^^^^^^^^^^^^^^^^^^^^^^^^^
  File "/home/ccl/anaconda3/envs/fedops_hyp/lib/python3.11/asyncio/queues.py", line 158, in get
    await getter
asyncio.exceptions.CancelledError

Error executing job with overrides: []
Traceback (most recent call last):
  File "/home/ccl/anaconda3/envs/fedops_hyp/lib/python3.11/site-packages/urllib3/connection.py", line 198, in _new_conn
    sock = connection.create_connection(
           ^^^^^^^^^^^^^^^^^^^^^^^^^^^^^
  File "/home/ccl/anaconda3/envs/fedops_hyp/lib/python3.11/site-packages/urllib3/util/connection.py", line 85, in create_connection
    raise err
  File "/home/ccl/anaconda3/envs/fedops_hyp/lib/python3.11/site-packages/urllib3/util/connection.py", line 73, in create_connection
    sock.connect(sa)
ConnectionRefusedError: [Errno 111] Connection refused

The above exception was the direct cause of the following exception:

Traceback (most recent call last):
  File "/home/ccl/anaconda3/envs/fedops_hyp/lib/python3.11/site-packages/urllib3/connectionpool.py", line 787, in urlopen
    response = self._make_request(
               ^^^^^^^^^^^^^^^^^^^
  File "/home/ccl/anaconda3/envs/fedops_hyp/lib/python3.11/site-packages/urllib3/connectionpool.py", line 493, in _make_request
    conn.request(
  File "/home/ccl/anaconda3/envs/fedops_hyp/lib/python3.11/site-packages/urllib3/connection.py", line 445, in request
    self.endheaders()
  File "/home/ccl/anaconda3/envs/fedops_hyp/lib/python3.11/http/client.py", line 1281, in endheaders
    self._send_output(message_body, encode_chunked=encode_chunked)
  File "/home/ccl/anaconda3/envs/fedops_hyp/lib/python3.11/http/client.py", line 1041, in _send_output
    self.send(msg)
  File "/home/ccl/anaconda3/envs/fedops_hyp/lib/python3.11/http/client.py", line 979, in send
    self.connect()
  File "/home/ccl/anaconda3/envs/fedops_hyp/lib/python3.11/site-packages/urllib3/connection.py", line 276, in connect
    self.sock = self._new_conn()
                ^^^^^^^^^^^^^^^^
  File "/home/ccl/anaconda3/envs/fedops_hyp/lib/python3.11/site-packages/urllib3/connection.py", line 213, in _new_conn
    raise NewConnectionError(
urllib3.exceptions.NewConnectionError: <urllib3.connection.HTTPConnection object at 0x7fbaa38f53d0>: Failed to establish a new connection: [Errno 111] Connection refused

The above exception was the direct cause of the following exception:

Traceback (most recent call last):
  File "/home/ccl/anaconda3/envs/fedops_hyp/lib/python3.11/site-packages/requests/adapters.py", line 667, in send
    resp = conn.urlopen(
           ^^^^^^^^^^^^^
  File "/home/ccl/anaconda3/envs/fedops_hyp/lib/python3.11/site-packages/urllib3/connectionpool.py", line 841, in urlopen
    retries = retries.increment(
              ^^^^^^^^^^^^^^^^^^
  File "/home/ccl/anaconda3/envs/fedops_hyp/lib/python3.11/site-packages/urllib3/util/retry.py", line 519, in increment
    raise MaxRetryError(_pool, url, reason) from reason  # type: ignore[arg-type]
    ^^^^^^^^^^^^^^^^^^^^^^^^^^^^^^^^^^^^^^^^^^^^^^^^^^^
urllib3.exceptions.MaxRetryError: HTTPConnectionPool(host='localhost', port=8004): Max retries exceeded with url: /flclient_out (Caused by NewConnectionError('<urllib3.connection.HTTPConnection object at 0x7fbaa38f53d0>: Failed to establish a new connection: [Errno 111] Connection refused'))

During handling of the above exception, another exception occurred:

Traceback (most recent call last):
  File "/home/ccl/safer/FedOps/MNIST/client_main.py", line 78, in main
    fl_client.start()
  File "/home/ccl/safer/FedOps/MNIST/app.py", line 247, in start
  File "/home/ccl/safer/FedOps/MNIST/client_api.py", line 36, in get_client_out
    requests.get(self.client_manager_addr + '/flclient_out')
  File "/home/ccl/anaconda3/envs/fedops_hyp/lib/python3.11/site-packages/requests/api.py", line 73, in get
    return request("get", url, params=params, **kwargs)
           ^^^^^^^^^^^^^^^^^^^^^^^^^^^^^^^^^^^^^^^^^^^^
  File "/home/ccl/anaconda3/envs/fedops_hyp/lib/python3.11/site-packages/requests/api.py", line 59, in request
    return session.request(method=method, url=url, **kwargs)
           ^^^^^^^^^^^^^^^^^^^^^^^^^^^^^^^^^^^^^^^^^^^^^^^^^
  File "/home/ccl/anaconda3/envs/fedops_hyp/lib/python3.11/site-packages/requests/sessions.py", line 589, in request
    resp = self.send(prep, **send_kwargs)
           ^^^^^^^^^^^^^^^^^^^^^^^^^^^^^^
  File "/home/ccl/anaconda3/envs/fedops_hyp/lib/python3.11/site-packages/requests/sessions.py", line 703, in send
    r = adapter.send(request, **kwargs)
        ^^^^^^^^^^^^^^^^^^^^^^^^^^^^^^^
  File "/home/ccl/anaconda3/envs/fedops_hyp/lib/python3.11/site-packages/requests/adapters.py", line 700, in send
    raise ConnectionError(e, request=request)
requests.exceptions.ConnectionError: HTTPConnectionPool(host='localhost', port=8004): Max retries exceeded with url: /flclient_out (Caused by NewConnectionError('<urllib3.connection.HTTPConnection object at 0x7fbaa38f53d0>: Failed to establish a new connection: [Errno 111] Connection refused'))

Set the environment variable HYDRA_FULL_ERROR=1 for a complete stack trace.
Exception ignored in: Exception in thread <module 'threading' from '/home/ccl/anaconda3/envs/fedops_hyp/lib/python3.11/threading.py'>Thread-13 (_do_shutdown)
:
Traceback (most recent call last):
  File "/home/ccl/anaconda3/envs/fedops_hyp/lib/python3.11/threading.py", line 1553, in _shutdown
Traceback (most recent call last):
      File "uvloop/loop.pyx", line 3254, in uvloop.loop.Loop._do_shutdown
atexit_call()
  File "/home/ccl/anaconda3/envs/fedops_hyp/lib/python3.11/concurrent/futures/thread.py", line 31, in _python_exit
      File "uvloop/loop.pyx", line 1290, in uvloop.loop.Loop.call_soon_threadsafe
t.join()
  File "/home/ccl/anaconda3/envs/fedops_hyp/lib/python3.11/threading.py", line 1112, in join
      File "uvloop/loop.pyx", line 673, in uvloop.loop.Loop._append_ready_handle
self._wait_for_tstate_lock()
  File "/home/ccl/anaconda3/envs/fedops_hyp/lib/python3.11/threading.py", line 1132, in _wait_for_tstate_lock
      File "uvloop/loop.pyx", line 705, in uvloop.loop.Loop._check_closed
if lock.acquire(block, timeout):
  RuntimeError :  Event loop is closed

^^During handling of the above exception, another exception occurred:
^^
^^Traceback (most recent call last):
^^  File "/home/ccl/anaconda3/envs/fedops_hyp/lib/python3.11/threading.py", line 1038, in _bootstrap_inner
^^^^    ^self.run()^
^^  File "/home/ccl/anaconda3/envs/fedops_hyp/lib/python3.11/threading.py", line 975, in run
^^    ^self._target(*self._args, **self._kwargs)^
^^  File "uvloop/loop.pyx", line 3256, in uvloop.loop.Loop._do_shutdown
^^^^^  File "uvloop/loop.pyx", line 1290, in uvloop.loop.Loop.call_soon_threadsafe
^
  File "uvloop/loop.pyx", line 673, in uvloop.loop.Loop._append_ready_handle
KeyboardInterrupt:   File "uvloop/loop.pyx", line 705, in uvloop.loop.Loop._check_closed

RuntimeError: Event loop is closed
Exception ignored in atexit callback: <function _start_and_connect_service.<locals>.teardown_atexit at 0x7fbaa3c6f100>
Traceback (most recent call last):
  File "/home/ccl/anaconda3/envs/fedops_hyp/lib/python3.11/site-packages/wandb/sdk/lib/service_connection.py", line 94, in teardown_atexit
    conn.teardown(hooks.exit_code)
  File "/home/ccl/anaconda3/envs/fedops_hyp/lib/python3.11/site-packages/wandb/sdk/lib/service_connection.py", line 226, in teardown
    self._router.join()
  File "/home/ccl/anaconda3/envs/fedops_hyp/lib/python3.11/site-packages/wandb/sdk/interface/router.py", line 75, in join
    self._thread.join()
  File "/home/ccl/anaconda3/envs/fedops_hyp/lib/python3.11/threading.py", line 1112, in join
    self._wait_for_tstate_lock()
  File "/home/ccl/anaconda3/envs/fedops_hyp/lib/python3.11/threading.py", line 1132, in _wait_for_tstate_lock
    if lock.acquire(block, timeout):
       ^^^^^^^^^^^^^^^^^^^^^^^^^^^^
KeyboardInterrupt:
