--- Logging error ---
Traceback (most recent call last):
  File "/home/ccl/safer/FedOps/MNIST/app.py", line 136, in fl_client_start
    client_start = client_fl.flower_client_start(self.status.server_IP, client)
                                                                        ^^^^^^
UnboundLocalError: cannot access local variable 'client' where it is not associated with a value

During handling of the above exception, another exception occurred:

Traceback (most recent call last):
  File "/home/ccl/anaconda3/envs/fedops_hyp/lib/python3.11/logging/__init__.py", line 1110, in emit
    msg = self.format(record)
          ^^^^^^^^^^^^^^^^^^^
  File "/home/ccl/anaconda3/envs/fedops_hyp/lib/python3.11/logging/__init__.py", line 953, in format
    return fmt.format(record)
           ^^^^^^^^^^^^^^^^^^
  File "/home/ccl/anaconda3/envs/fedops_hyp/lib/python3.11/logging/__init__.py", line 687, in format
    record.message = record.getMessage()
                     ^^^^^^^^^^^^^^^^^^^
  File "/home/ccl/anaconda3/envs/fedops_hyp/lib/python3.11/logging/__init__.py", line 377, in getMessage
    msg = msg % self.args
          ~~~~^~~~~~~~~~~
TypeError: not all arguments converted during string formatting
Call stack:
  File "/home/ccl/safer/FedOps/MNIST/client_main.py", line 82, in <module>
    main()
  File "/home/ccl/anaconda3/envs/fedops_hyp/lib/python3.11/site-packages/hydra/main.py", line 94, in decorated_main
    _run_hydra(
  File "/home/ccl/anaconda3/envs/fedops_hyp/lib/python3.11/site-packages/hydra/_internal/utils.py", line 394, in _run_hydra
    _run_app(
  File "/home/ccl/anaconda3/envs/fedops_hyp/lib/python3.11/site-packages/hydra/_internal/utils.py", line 457, in _run_app
    run_and_report(
  File "/home/ccl/anaconda3/envs/fedops_hyp/lib/python3.11/site-packages/hydra/_internal/utils.py", line 220, in run_and_report
    return func()
  File "/home/ccl/anaconda3/envs/fedops_hyp/lib/python3.11/site-packages/hydra/_internal/utils.py", line 458, in <lambda>
    lambda: hydra.run(
  File "/home/ccl/anaconda3/envs/fedops_hyp/lib/python3.11/site-packages/hydra/_internal/hydra.py", line 119, in run
    ret = run_job(
  File "/home/ccl/anaconda3/envs/fedops_hyp/lib/python3.11/site-packages/hydra/core/utils.py", line 186, in run_job
    ret.return_value = task_function(task_cfg)
  File "/home/ccl/safer/FedOps/MNIST/client_main.py", line 78, in main
    fl_client.start()
  File "/home/ccl/safer/FedOps/MNIST/app.py", line 224, in start
    uvicorn.run(self.app, host='0.0.0.0', port=self.client_port)
  File "/home/ccl/anaconda3/envs/fedops_hyp/lib/python3.11/site-packages/uvicorn/main.py", line 579, in run
    server.run()
  File "/home/ccl/anaconda3/envs/fedops_hyp/lib/python3.11/site-packages/uvicorn/server.py", line 66, in run
    return asyncio.run(self.serve(sockets=sockets))
  File "/home/ccl/anaconda3/envs/fedops_hyp/lib/python3.11/asyncio/runners.py", line 190, in run
    return runner.run(main)
  File "/home/ccl/anaconda3/envs/fedops_hyp/lib/python3.11/asyncio/runners.py", line 118, in run
    return self._loop.run_until_complete(task)
  File "/home/ccl/anaconda3/envs/fedops_hyp/lib/python3.11/site-packages/uvicorn/protocols/http/httptools_impl.py", line 409, in run_asgi
    result = await app(  # type: ignore[func-returns-value]
  File "/home/ccl/anaconda3/envs/fedops_hyp/lib/python3.11/site-packages/uvicorn/middleware/proxy_headers.py", line 60, in __call__
    return await self.app(scope, receive, send)
  File "/home/ccl/anaconda3/envs/fedops_hyp/lib/python3.11/site-packages/fastapi/applications.py", line 1054, in __call__
    await super().__call__(scope, receive, send)
  File "/home/ccl/anaconda3/envs/fedops_hyp/lib/python3.11/site-packages/starlette/applications.py", line 112, in __call__
    await self.middleware_stack(scope, receive, send)
  File "/home/ccl/anaconda3/envs/fedops_hyp/lib/python3.11/site-packages/starlette/middleware/errors.py", line 165, in __call__
    await self.app(scope, receive, _send)
  File "/home/ccl/anaconda3/envs/fedops_hyp/lib/python3.11/site-packages/starlette/middleware/exceptions.py", line 62, in __call__
    await wrap_app_handling_exceptions(self.app, conn)(scope, receive, send)
  File "/home/ccl/anaconda3/envs/fedops_hyp/lib/python3.11/site-packages/starlette/_exception_handler.py", line 42, in wrapped_app
    await app(scope, receive, sender)
  File "/home/ccl/anaconda3/envs/fedops_hyp/lib/python3.11/site-packages/starlette/routing.py", line 714, in __call__
    await self.middleware_stack(scope, receive, send)
  File "/home/ccl/anaconda3/envs/fedops_hyp/lib/python3.11/site-packages/starlette/routing.py", line 734, in app
    await route.handle(scope, receive, send)
  File "/home/ccl/anaconda3/envs/fedops_hyp/lib/python3.11/site-packages/starlette/routing.py", line 288, in handle
    await self.app(scope, receive, send)
  File "/home/ccl/anaconda3/envs/fedops_hyp/lib/python3.11/site-packages/starlette/routing.py", line 76, in app
    await wrap_app_handling_exceptions(app, request)(scope, receive, send)
  File "/home/ccl/anaconda3/envs/fedops_hyp/lib/python3.11/site-packages/starlette/_exception_handler.py", line 42, in wrapped_app
    await app(scope, receive, sender)
  File "/home/ccl/anaconda3/envs/fedops_hyp/lib/python3.11/site-packages/starlette/routing.py", line 74, in app
    await response(scope, receive, send)
  File "/home/ccl/anaconda3/envs/fedops_hyp/lib/python3.11/site-packages/starlette/responses.py", line 160, in __call__
    await self.background()
  File "/home/ccl/anaconda3/envs/fedops_hyp/lib/python3.11/site-packages/starlette/background.py", line 41, in __call__
    await task()
  File "/home/ccl/anaconda3/envs/fedops_hyp/lib/python3.11/site-packages/starlette/background.py", line 26, in __call__
    await self.func(*self.args, **self.kwargs)
  File "/home/ccl/safer/FedOps/MNIST/app.py", line 181, in fl_client_start
    logging.info('[E][PC0002] learning', e)
Message: '[E][PC0002] learning'
Arguments: (UnboundLocalError("cannot access local variable 'client' where it is not associated with a value"),)
--- Logging error ---
Traceback (most recent call last):
  File "/home/ccl/safer/FedOps/MNIST/app.py", line 136, in fl_client_start
    client_start = client_fl.flower_client_start(self.status.server_IP, client)
                                                                        ^^^^^^
UnboundLocalError: cannot access local variable 'client' where it is not associated with a value

During handling of the above exception, another exception occurred:

Traceback (most recent call last):
  File "/home/ccl/anaconda3/envs/fedops_hyp/lib/python3.11/logging/__init__.py", line 1110, in emit
    msg = self.format(record)
          ^^^^^^^^^^^^^^^^^^^
  File "/home/ccl/anaconda3/envs/fedops_hyp/lib/python3.11/logging/__init__.py", line 953, in format
    return fmt.format(record)
           ^^^^^^^^^^^^^^^^^^
  File "/home/ccl/anaconda3/envs/fedops_hyp/lib/python3.11/logging/__init__.py", line 687, in format
    record.message = record.getMessage()
                     ^^^^^^^^^^^^^^^^^^^
  File "/home/ccl/anaconda3/envs/fedops_hyp/lib/python3.11/logging/__init__.py", line 377, in getMessage
    msg = msg % self.args
          ~~~~^~~~~~~~~~~
TypeError: not all arguments converted during string formatting
Call stack:
  File "/home/ccl/safer/FedOps/MNIST/client_main.py", line 82, in <module>
    main()
  File "/home/ccl/anaconda3/envs/fedops_hyp/lib/python3.11/site-packages/hydra/main.py", line 94, in decorated_main
    _run_hydra(
  File "/home/ccl/anaconda3/envs/fedops_hyp/lib/python3.11/site-packages/hydra/_internal/utils.py", line 394, in _run_hydra
    _run_app(
  File "/home/ccl/anaconda3/envs/fedops_hyp/lib/python3.11/site-packages/hydra/_internal/utils.py", line 457, in _run_app
    run_and_report(
  File "/home/ccl/anaconda3/envs/fedops_hyp/lib/python3.11/site-packages/hydra/_internal/utils.py", line 220, in run_and_report
    return func()
  File "/home/ccl/anaconda3/envs/fedops_hyp/lib/python3.11/site-packages/hydra/_internal/utils.py", line 458, in <lambda>
    lambda: hydra.run(
  File "/home/ccl/anaconda3/envs/fedops_hyp/lib/python3.11/site-packages/hydra/_internal/hydra.py", line 119, in run
    ret = run_job(
  File "/home/ccl/anaconda3/envs/fedops_hyp/lib/python3.11/site-packages/hydra/core/utils.py", line 186, in run_job
    ret.return_value = task_function(task_cfg)
  File "/home/ccl/safer/FedOps/MNIST/client_main.py", line 78, in main
    fl_client.start()
  File "/home/ccl/safer/FedOps/MNIST/app.py", line 224, in start
    uvicorn.run(self.app, host='0.0.0.0', port=self.client_port)
  File "/home/ccl/anaconda3/envs/fedops_hyp/lib/python3.11/site-packages/uvicorn/main.py", line 579, in run
    server.run()
  File "/home/ccl/anaconda3/envs/fedops_hyp/lib/python3.11/site-packages/uvicorn/server.py", line 66, in run
    return asyncio.run(self.serve(sockets=sockets))
  File "/home/ccl/anaconda3/envs/fedops_hyp/lib/python3.11/asyncio/runners.py", line 190, in run
    return runner.run(main)
  File "/home/ccl/anaconda3/envs/fedops_hyp/lib/python3.11/asyncio/runners.py", line 118, in run
    return self._loop.run_until_complete(task)
  File "/home/ccl/anaconda3/envs/fedops_hyp/lib/python3.11/site-packages/uvicorn/protocols/http/httptools_impl.py", line 409, in run_asgi
    result = await app(  # type: ignore[func-returns-value]
  File "/home/ccl/anaconda3/envs/fedops_hyp/lib/python3.11/site-packages/uvicorn/middleware/proxy_headers.py", line 60, in __call__
    return await self.app(scope, receive, send)
  File "/home/ccl/anaconda3/envs/fedops_hyp/lib/python3.11/site-packages/fastapi/applications.py", line 1054, in __call__
    await super().__call__(scope, receive, send)
  File "/home/ccl/anaconda3/envs/fedops_hyp/lib/python3.11/site-packages/starlette/applications.py", line 112, in __call__
    await self.middleware_stack(scope, receive, send)
  File "/home/ccl/anaconda3/envs/fedops_hyp/lib/python3.11/site-packages/starlette/middleware/errors.py", line 165, in __call__
    await self.app(scope, receive, _send)
  File "/home/ccl/anaconda3/envs/fedops_hyp/lib/python3.11/site-packages/starlette/middleware/exceptions.py", line 62, in __call__
    await wrap_app_handling_exceptions(self.app, conn)(scope, receive, send)
  File "/home/ccl/anaconda3/envs/fedops_hyp/lib/python3.11/site-packages/starlette/_exception_handler.py", line 42, in wrapped_app
    await app(scope, receive, sender)
  File "/home/ccl/anaconda3/envs/fedops_hyp/lib/python3.11/site-packages/starlette/routing.py", line 714, in __call__
    await self.middleware_stack(scope, receive, send)
  File "/home/ccl/anaconda3/envs/fedops_hyp/lib/python3.11/site-packages/starlette/routing.py", line 734, in app
    await route.handle(scope, receive, send)
  File "/home/ccl/anaconda3/envs/fedops_hyp/lib/python3.11/site-packages/starlette/routing.py", line 288, in handle
    await self.app(scope, receive, send)
  File "/home/ccl/anaconda3/envs/fedops_hyp/lib/python3.11/site-packages/starlette/routing.py", line 76, in app
    await wrap_app_handling_exceptions(app, request)(scope, receive, send)
  File "/home/ccl/anaconda3/envs/fedops_hyp/lib/python3.11/site-packages/starlette/_exception_handler.py", line 42, in wrapped_app
    await app(scope, receive, sender)
  File "/home/ccl/anaconda3/envs/fedops_hyp/lib/python3.11/site-packages/starlette/routing.py", line 74, in app
    await response(scope, receive, send)
  File "/home/ccl/anaconda3/envs/fedops_hyp/lib/python3.11/site-packages/starlette/responses.py", line 160, in __call__
    await self.background()
  File "/home/ccl/anaconda3/envs/fedops_hyp/lib/python3.11/site-packages/starlette/background.py", line 41, in __call__
    await task()
  File "/home/ccl/anaconda3/envs/fedops_hyp/lib/python3.11/site-packages/starlette/background.py", line 26, in __call__
    await self.func(*self.args, **self.kwargs)
  File "/home/ccl/safer/FedOps/MNIST/app.py", line 181, in fl_client_start
    logging.info('[E][PC0002] learning', e)
Message: '[E][PC0002] learning'
Arguments: (UnboundLocalError("cannot access local variable 'client' where it is not associated with a value"),)
[2025-04-08 16:53:11,492][root][INFO] - notify_fail start
[2025-04-08 16:53:11,514][root][ERROR] - trainFin
[31mERROR[0m:    Exception in ASGI application
Traceback (most recent call last):
  File "/home/ccl/anaconda3/envs/fedops_hyp/lib/python3.11/site-packages/uvicorn/protocols/http/httptools_impl.py", line 409, in run_asgi
    result = await app(  # type: ignore[func-returns-value]
             ^^^^^^^^^^^^^^^^^^^^^^^^^^^^^^^^^^^^^^^^^^^^^^
  File "/home/ccl/anaconda3/envs/fedops_hyp/lib/python3.11/site-packages/uvicorn/middleware/proxy_headers.py", line 60, in __call__
    return await self.app(scope, receive, send)
           ^^^^^^^^^^^^^^^^^^^^^^^^^^^^^^^^^^^^
  File "/home/ccl/anaconda3/envs/fedops_hyp/lib/python3.11/site-packages/fastapi/applications.py", line 1054, in __call__
    await super().__call__(scope, receive, send)
  File "/home/ccl/anaconda3/envs/fedops_hyp/lib/python3.11/site-packages/starlette/applications.py", line 112, in __call__
    await self.middleware_stack(scope, receive, send)
  File "/home/ccl/anaconda3/envs/fedops_hyp/lib/python3.11/site-packages/starlette/middleware/errors.py", line 187, in __call__
    raise exc
  File "/home/ccl/anaconda3/envs/fedops_hyp/lib/python3.11/site-packages/starlette/middleware/errors.py", line 165, in __call__
    await self.app(scope, receive, _send)
  File "/home/ccl/anaconda3/envs/fedops_hyp/lib/python3.11/site-packages/starlette/middleware/exceptions.py", line 62, in __call__
    await wrap_app_handling_exceptions(self.app, conn)(scope, receive, send)
  File "/home/ccl/anaconda3/envs/fedops_hyp/lib/python3.11/site-packages/starlette/_exception_handler.py", line 53, in wrapped_app
    raise exc
  File "/home/ccl/anaconda3/envs/fedops_hyp/lib/python3.11/site-packages/starlette/_exception_handler.py", line 42, in wrapped_app
    await app(scope, receive, sender)
  File "/home/ccl/anaconda3/envs/fedops_hyp/lib/python3.11/site-packages/starlette/routing.py", line 714, in __call__
    await self.middleware_stack(scope, receive, send)
  File "/home/ccl/anaconda3/envs/fedops_hyp/lib/python3.11/site-packages/starlette/routing.py", line 734, in app
    await route.handle(scope, receive, send)
  File "/home/ccl/anaconda3/envs/fedops_hyp/lib/python3.11/site-packages/starlette/routing.py", line 288, in handle
    await self.app(scope, receive, send)
  File "/home/ccl/anaconda3/envs/fedops_hyp/lib/python3.11/site-packages/starlette/routing.py", line 76, in app
    await wrap_app_handling_exceptions(app, request)(scope, receive, send)
  File "/home/ccl/anaconda3/envs/fedops_hyp/lib/python3.11/site-packages/starlette/_exception_handler.py", line 53, in wrapped_app
    raise exc
  File "/home/ccl/anaconda3/envs/fedops_hyp/lib/python3.11/site-packages/starlette/_exception_handler.py", line 42, in wrapped_app
    await app(scope, receive, sender)
  File "/home/ccl/anaconda3/envs/fedops_hyp/lib/python3.11/site-packages/starlette/routing.py", line 74, in app
    await response(scope, receive, send)
  File "/home/ccl/anaconda3/envs/fedops_hyp/lib/python3.11/site-packages/starlette/responses.py", line 160, in __call__
    await self.background()
  File "/home/ccl/anaconda3/envs/fedops_hyp/lib/python3.11/site-packages/starlette/background.py", line 41, in __call__
    await task()
  File "/home/ccl/anaconda3/envs/fedops_hyp/lib/python3.11/site-packages/starlette/background.py", line 26, in __call__
    await self.func(*self.args, **self.kwargs)
  File "/home/ccl/safer/FedOps/MNIST/app.py", line 184, in fl_client_start
    raise e
  File "/home/ccl/safer/FedOps/MNIST/app.py", line 136, in fl_client_start
    client_start = client_fl.flower_client_start(self.status.server_IP, client)
                                                                        ^^^^^^
UnboundLocalError: cannot access local variable 'client' where it is not associated with a value
[32mINFO[0m:     127.0.0.1:34848 - "[1mGET /online HTTP/1.1[0m" [32m200 OK[0m
[32mINFO[0m:     127.0.0.1:39984 - "[1mGET /online HTTP/1.1[0m" [32m200 OK[0m
[32mINFO[0m:     127.0.0.1:50822 - "[1mGET /online HTTP/1.1[0m" [32m200 OK[0m
[32mINFO[0m:     127.0.0.1:50832 - "[1mGET /online HTTP/1.1[0m" [32m200 OK[0m
[32mINFO[0m:     127.0.0.1:40214 - "[1mGET /online HTTP/1.1[0m" [32m200 OK[0m
[32mINFO[0m:     127.0.0.1:40220 - "[1mGET /online HTTP/1.1[0m" [32m200 OK[0m
[32mINFO[0m:     127.0.0.1:51962 - "[1mGET /online HTTP/1.1[0m" [32m200 OK[0m
[32mINFO[0m:     127.0.0.1:55174 - "[1mGET /online HTTP/1.1[0m" [32m200 OK[0m
[32mINFO[0m:     127.0.0.1:55176 - "[1mGET /online HTTP/1.1[0m" [32m200 OK[0m
[32mINFO[0m:     127.0.0.1:48738 - "[1mGET /online HTTP/1.1[0m" [32m200 OK[0m
[32mINFO[0m:     127.0.0.1:37040 - "[1mGET /online HTTP/1.1[0m" [32m200 OK[0m
[32mINFO[0m:     127.0.0.1:37044 - "[1mGET /online HTTP/1.1[0m" [32m200 OK[0m
[32mINFO[0m:     127.0.0.1:59642 - "[1mGET /online HTTP/1.1[0m" [32m200 OK[0m
[32mINFO[0m:     127.0.0.1:49736 - "[1mGET /online HTTP/1.1[0m" [32m200 OK[0m
[32mINFO[0m:     127.0.0.1:49738 - "[1mGET /online HTTP/1.1[0m" [32m200 OK[0m
[32mINFO[0m:     127.0.0.1:55950 - "[1mGET /online HTTP/1.1[0m" [32m200 OK[0m
[32mINFO[0m:     127.0.0.1:45952 - "[1mGET /online HTTP/1.1[0m" [32m200 OK[0m
[32mINFO[0m:     127.0.0.1:45966 - "[1mGET /online HTTP/1.1[0m" [32m200 OK[0m
[32mINFO[0m:     127.0.0.1:54702 - "[1mGET /online HTTP/1.1[0m" [32m200 OK[0m
[32mINFO[0m:     127.0.0.1:57762 - "[1mGET /online HTTP/1.1[0m" [32m200 OK[0m
[32mINFO[0m:     127.0.0.1:57776 - "[1mGET /online HTTP/1.1[0m" [32m200 OK[0m
[32mINFO[0m:     127.0.0.1:51100 - "[1mGET /online HTTP/1.1[0m" [32m200 OK[0m
[32mINFO[0m:     127.0.0.1:44676 - "[1mGET /online HTTP/1.1[0m" [32m200 OK[0m
[32mINFO[0m:     127.0.0.1:44682 - "[1mGET /online HTTP/1.1[0m" [32m200 OK[0m
[32mINFO[0m:     127.0.0.1:35836 - "[1mGET /online HTTP/1.1[0m" [32m200 OK[0m
[32mINFO[0m:     127.0.0.1:53984 - "[1mGET /online HTTP/1.1[0m" [32m200 OK[0m
[32mINFO[0m:     127.0.0.1:53988 - "[1mGET /online HTTP/1.1[0m" [32m200 OK[0m
[32mINFO[0m:     127.0.0.1:33924 - "[1mGET /online HTTP/1.1[0m" [32m200 OK[0m
[32mINFO[0m:     127.0.0.1:33926 - "[1mGET /online HTTP/1.1[0m" [32m200 OK[0m
[32mINFO[0m:     127.0.0.1:41106 - "[1mGET /online HTTP/1.1[0m" [32m200 OK[0m
[32mINFO[0m:     127.0.0.1:32814 - "[1mGET /online HTTP/1.1[0m" [32m200 OK[0m
[32mINFO[0m:     127.0.0.1:32816 - "[1mGET /online HTTP/1.1[0m" [32m200 OK[0m
[32mINFO[0m:     127.0.0.1:55556 - "[1mGET /online HTTP/1.1[0m" [32m200 OK[0m
[32mINFO[0m:     127.0.0.1:41824 - "[1mGET /online HTTP/1.1[0m" [32m200 OK[0m
[32mINFO[0m:     127.0.0.1:41826 - "[1mGET /online HTTP/1.1[0m" [32m200 OK[0m
[32mINFO[0m:     127.0.0.1:38998 - "[1mGET /online HTTP/1.1[0m" [32m200 OK[0m
[32mINFO[0m:     127.0.0.1:36884 - "[1mGET /online HTTP/1.1[0m" [32m200 OK[0m
[32mINFO[0m:     127.0.0.1:36888 - "[1mGET /online HTTP/1.1[0m" [32m200 OK[0m
[32mINFO[0m:     127.0.0.1:47996 - "[1mGET /online HTTP/1.1[0m" [32m200 OK[0m
[32mINFO[0m:     127.0.0.1:57340 - "[1mGET /online HTTP/1.1[0m" [32m200 OK[0m
[32mINFO[0m:     127.0.0.1:57344 - "[1mGET /online HTTP/1.1[0m" [32m200 OK[0m
[32mINFO[0m:     127.0.0.1:41346 - "[1mGET /online HTTP/1.1[0m" [32m200 OK[0m
[32mINFO[0m:     127.0.0.1:59778 - "[1mGET /online HTTP/1.1[0m" [32m200 OK[0m
[32mINFO[0m:     127.0.0.1:59782 - "[1mGET /online HTTP/1.1[0m" [32m200 OK[0m
[32mINFO[0m:     127.0.0.1:56906 - "[1mGET /online HTTP/1.1[0m" [32m200 OK[0m
[32mINFO[0m:     127.0.0.1:41002 - "[1mGET /online HTTP/1.1[0m" [32m200 OK[0m
[32mINFO[0m:     127.0.0.1:41016 - "[1mGET /online HTTP/1.1[0m" [32m200 OK[0m
[32mINFO[0m:     127.0.0.1:59082 - "[1mGET /online HTTP/1.1[0m" [32m200 OK[0m
[32mINFO[0m:     127.0.0.1:39846 - "[1mGET /online HTTP/1.1[0m" [32m200 OK[0m
[32mINFO[0m:     127.0.0.1:39862 - "[1mGET /online HTTP/1.1[0m" [32m200 OK[0m
[32mINFO[0m:     127.0.0.1:33320 - "[1mGET /online HTTP/1.1[0m" [32m200 OK[0m
[32mINFO[0m:     127.0.0.1:33324 - "[1mGET /online HTTP/1.1[0m" [32m200 OK[0m
[32mINFO[0m:     127.0.0.1:37408 - "[1mGET /online HTTP/1.1[0m" [32m200 OK[0m
[32mINFO[0m:     127.0.0.1:36102 - "[1mGET /online HTTP/1.1[0m" [32m200 OK[0m
[32mINFO[0m:     127.0.0.1:36104 - "[1mGET /online HTTP/1.1[0m" [32m200 OK[0m
[32mINFO[0m:     127.0.0.1:35508 - "[1mGET /online HTTP/1.1[0m" [32m200 OK[0m
[32mINFO[0m:     127.0.0.1:34088 - "[1mGET /online HTTP/1.1[0m" [32m200 OK[0m
[32mINFO[0m:     127.0.0.1:34096 - "[1mGET /online HTTP/1.1[0m" [32m200 OK[0m
[32mINFO[0m:     127.0.0.1:34220 - "[1mGET /online HTTP/1.1[0m" [32m200 OK[0m
[32mINFO[0m:     127.0.0.1:50732 - "[1mGET /online HTTP/1.1[0m" [32m200 OK[0m
[32mINFO[0m:     127.0.0.1:50740 - "[1mGET /online HTTP/1.1[0m" [32m200 OK[0m
[32mINFO[0m:     127.0.0.1:57820 - "[1mGET /online HTTP/1.1[0m" [32m200 OK[0m
[32mINFO[0m:     127.0.0.1:59724 - "[1mGET /online HTTP/1.1[0m" [32m200 OK[0m
[32mINFO[0m:     127.0.0.1:59728 - "[1mGET /online HTTP/1.1[0m" [32m200 OK[0m
[32mINFO[0m:     127.0.0.1:59938 - "[1mGET /online HTTP/1.1[0m" [32m200 OK[0m
[32mINFO[0m:     127.0.0.1:48148 - "[1mGET /online HTTP/1.1[0m" [32m200 OK[0m
[32mINFO[0m:     127.0.0.1:48164 - "[1mGET /online HTTP/1.1[0m" [32m200 OK[0m
[32mINFO[0m:     127.0.0.1:42632 - "[1mGET /online HTTP/1.1[0m" [32m200 OK[0m
[32mINFO[0m:     127.0.0.1:52126 - "[1mGET /online HTTP/1.1[0m" [32m200 OK[0m
[32mINFO[0m:     127.0.0.1:52140 - "[1mGET /online HTTP/1.1[0m" [32m200 OK[0m
[32mINFO[0m:     127.0.0.1:47340 - "[1mGET /online HTTP/1.1[0m" [32m200 OK[0m
[32mINFO[0m:     127.0.0.1:56508 - "[1mGET /online HTTP/1.1[0m" [32m200 OK[0m
[32mINFO[0m:     127.0.0.1:56512 - "[1mGET /online HTTP/1.1[0m" [32m200 OK[0m
[32mINFO[0m:     127.0.0.1:53954 - "[1mGET /online HTTP/1.1[0m" [32m200 OK[0m
[32mINFO[0m:     127.0.0.1:53962 - "[1mGET /online HTTP/1.1[0m" [32m200 OK[0m
[32mINFO[0m:     127.0.0.1:35522 - "[1mGET /online HTTP/1.1[0m" [32m200 OK[0m
[32mINFO[0m:     127.0.0.1:44482 - "[1mGET /online HTTP/1.1[0m" [32m200 OK[0m
[32mINFO[0m:     127.0.0.1:44488 - "[1mGET /online HTTP/1.1[0m" [32m200 OK[0m
[32mINFO[0m:     127.0.0.1:47694 - "[1mGET /online HTTP/1.1[0m" [32m200 OK[0m
[32mINFO[0m:     127.0.0.1:50118 - "[1mGET /online HTTP/1.1[0m" [32m200 OK[0m
[32mINFO[0m:     127.0.0.1:50120 - "[1mGET /online HTTP/1.1[0m" [32m200 OK[0m
[32mINFO[0m:     127.0.0.1:39104 - "[1mGET /online HTTP/1.1[0m" [32m200 OK[0m
[32mINFO[0m:     127.0.0.1:45958 - "[1mGET /online HTTP/1.1[0m" [32m200 OK[0m
[32mINFO[0m:     127.0.0.1:45972 - "[1mGET /online HTTP/1.1[0m" [32m200 OK[0m
[32mINFO[0m:     127.0.0.1:52074 - "[1mGET /online HTTP/1.1[0m" [32m200 OK[0m
[32mINFO[0m:     127.0.0.1:52280 - "[1mGET /online HTTP/1.1[0m" [32m200 OK[0m
[32mINFO[0m:     127.0.0.1:52286 - "[1mGET /online HTTP/1.1[0m" [32m200 OK[0m
[32mINFO[0m:     127.0.0.1:53048 - "[1mGET /online HTTP/1.1[0m" [32m200 OK[0m
[32mINFO[0m:     127.0.0.1:50542 - "[1mGET /online HTTP/1.1[0m" [32m200 OK[0m
[32mINFO[0m:     127.0.0.1:50550 - "[1mGET /online HTTP/1.1[0m" [32m200 OK[0m
[32mINFO[0m:     127.0.0.1:57716 - "[1mGET /online HTTP/1.1[0m" [32m200 OK[0m
[32mINFO[0m:     127.0.0.1:41800 - "[1mGET /online HTTP/1.1[0m" [32m200 OK[0m
[32mINFO[0m:     127.0.0.1:41810 - "[1mGET /online HTTP/1.1[0m" [32m200 OK[0m
[32mINFO[0m:     127.0.0.1:47360 - "[1mGET /online HTTP/1.1[0m" [32m200 OK[0m
[32mINFO[0m:     127.0.0.1:45224 - "[1mGET /online HTTP/1.1[0m" [32m200 OK[0m
[32mINFO[0m:     127.0.0.1:45230 - "[1mGET /online HTTP/1.1[0m" [32m200 OK[0m
[32mINFO[0m:     127.0.0.1:38466 - "[1mGET /online HTTP/1.1[0m" [32m200 OK[0m
[32mINFO[0m:     127.0.0.1:38480 - "[1mGET /online HTTP/1.1[0m" [32m200 OK[0m
[32mINFO[0m:     127.0.0.1:35216 - "[1mGET /online HTTP/1.1[0m" [32m200 OK[0m
[32mINFO[0m:     127.0.0.1:54666 - "[1mGET /online HTTP/1.1[0m" [32m200 OK[0m
[32mINFO[0m:     127.0.0.1:54682 - "[1mGET /online HTTP/1.1[0m" [32m200 OK[0m
[32mINFO[0m:     127.0.0.1:49680 - "[1mGET /online HTTP/1.1[0m" [32m200 OK[0m
[32mINFO[0m:     127.0.0.1:58644 - "[1mGET /online HTTP/1.1[0m" [32m200 OK[0m
[32mINFO[0m:     127.0.0.1:58658 - "[1mGET /online HTTP/1.1[0m" [32m200 OK[0m
[32mINFO[0m:     127.0.0.1:55724 - "[1mGET /online HTTP/1.1[0m" [32m200 OK[0m
[32mINFO[0m:     127.0.0.1:42316 - "[1mGET /online HTTP/1.1[0m" [32m200 OK[0m
[32mINFO[0m:     127.0.0.1:42322 - "[1mGET /online HTTP/1.1[0m" [32m200 OK[0m
[32mINFO[0m:     127.0.0.1:56056 - "[1mGET /online HTTP/1.1[0m" [32m200 OK[0m
[32mINFO[0m:     127.0.0.1:47236 - "[1mGET /online HTTP/1.1[0m" [32m200 OK[0m
[32mINFO[0m:     127.0.0.1:47244 - "[1mGET /online HTTP/1.1[0m" [32m200 OK[0m
[32mINFO[0m:     127.0.0.1:44364 - "[1mGET /online HTTP/1.1[0m" [32m200 OK[0m
[32mINFO[0m:     127.0.0.1:47324 - "[1mGET /online HTTP/1.1[0m" [32m200 OK[0m
[32mINFO[0m:     127.0.0.1:47336 - "[1mGET /online HTTP/1.1[0m" [32m200 OK[0m
[32mINFO[0m:     127.0.0.1:46528 - "[1mGET /online HTTP/1.1[0m" [32m200 OK[0m
[32mINFO[0m:     127.0.0.1:54710 - "[1mGET /online HTTP/1.1[0m" [32m200 OK[0m
[32mINFO[0m:     127.0.0.1:54722 - "[1mGET /online HTTP/1.1[0m" [32m200 OK[0m
[32mINFO[0m:     127.0.0.1:54450 - "[1mGET /online HTTP/1.1[0m" [32m200 OK[0m
[32mINFO[0m:     127.0.0.1:34404 - "[1mGET /online HTTP/1.1[0m" [32m200 OK[0m
[32mINFO[0m:     127.0.0.1:34420 - "[1mGET /online HTTP/1.1[0m" [32m200 OK[0m
[32mINFO[0m:     127.0.0.1:58572 - "[1mGET /online HTTP/1.1[0m" [32m200 OK[0m
[32mINFO[0m:     Shutting down
[32mINFO[0m:     Waiting for application shutdown.
[32mINFO[0m:     Application shutdown complete.
[32mINFO[0m:     Finished server process [[36m1993634[0m]
Error executing job with overrides: []
Traceback (most recent call last):
  File "/home/ccl/anaconda3/envs/fedops_hyp/lib/python3.11/site-packages/urllib3/connection.py", line 198, in _new_conn
    sock = connection.create_connection(
           ^^^^^^^^^^^^^^^^^^^^^^^^^^^^^
  File "/home/ccl/anaconda3/envs/fedops_hyp/lib/python3.11/site-packages/urllib3/util/connection.py", line 85, in create_connection
    raise err
  File "/home/ccl/anaconda3/envs/fedops_hyp/lib/python3.11/site-packages/urllib3/util/connection.py", line 73, in create_connection
    sock.connect(sa)
ConnectionRefusedError: [Errno 111] Connection refused

The above exception was the direct cause of the following exception:

Traceback (most recent call last):
  File "/home/ccl/anaconda3/envs/fedops_hyp/lib/python3.11/site-packages/urllib3/connectionpool.py", line 787, in urlopen
    response = self._make_request(
               ^^^^^^^^^^^^^^^^^^^
  File "/home/ccl/anaconda3/envs/fedops_hyp/lib/python3.11/site-packages/urllib3/connectionpool.py", line 493, in _make_request
    conn.request(
  File "/home/ccl/anaconda3/envs/fedops_hyp/lib/python3.11/site-packages/urllib3/connection.py", line 445, in request
    self.endheaders()
  File "/home/ccl/anaconda3/envs/fedops_hyp/lib/python3.11/http/client.py", line 1281, in endheaders
    self._send_output(message_body, encode_chunked=encode_chunked)
  File "/home/ccl/anaconda3/envs/fedops_hyp/lib/python3.11/http/client.py", line 1041, in _send_output
    self.send(msg)
  File "/home/ccl/anaconda3/envs/fedops_hyp/lib/python3.11/http/client.py", line 979, in send
    self.connect()
  File "/home/ccl/anaconda3/envs/fedops_hyp/lib/python3.11/site-packages/urllib3/connection.py", line 276, in connect
    self.sock = self._new_conn()
                ^^^^^^^^^^^^^^^^
  File "/home/ccl/anaconda3/envs/fedops_hyp/lib/python3.11/site-packages/urllib3/connection.py", line 213, in _new_conn
    raise NewConnectionError(
urllib3.exceptions.NewConnectionError: <urllib3.connection.HTTPConnection object at 0x7fb343140750>: Failed to establish a new connection: [Errno 111] Connection refused

The above exception was the direct cause of the following exception:

Traceback (most recent call last):
  File "/home/ccl/anaconda3/envs/fedops_hyp/lib/python3.11/site-packages/requests/adapters.py", line 667, in send
    resp = conn.urlopen(
           ^^^^^^^^^^^^^
  File "/home/ccl/anaconda3/envs/fedops_hyp/lib/python3.11/site-packages/urllib3/connectionpool.py", line 841, in urlopen
    retries = retries.increment(
              ^^^^^^^^^^^^^^^^^^
  File "/home/ccl/anaconda3/envs/fedops_hyp/lib/python3.11/site-packages/urllib3/util/retry.py", line 519, in increment
    raise MaxRetryError(_pool, url, reason) from reason  # type: ignore[arg-type]
    ^^^^^^^^^^^^^^^^^^^^^^^^^^^^^^^^^^^^^^^^^^^^^^^^^^^
urllib3.exceptions.MaxRetryError: HTTPConnectionPool(host='localhost', port=8004): Max retries exceeded with url: /flclient_out (Caused by NewConnectionError('<urllib3.connection.HTTPConnection object at 0x7fb343140750>: Failed to establish a new connection: [Errno 111] Connection refused'))

During handling of the above exception, another exception occurred:

Traceback (most recent call last):
  File "/home/ccl/safer/FedOps/MNIST/client_main.py", line 78, in main
    fl_client.start()
  File "/home/ccl/safer/FedOps/MNIST/app.py", line 232, in start
    client_api.ClientMangerAPI().get_client_out()
  File "/home/ccl/safer/FedOps/MNIST/client_api.py", line 36, in get_client_out
    requests.get(self.client_manager_addr + '/flclient_out')
  File "/home/ccl/anaconda3/envs/fedops_hyp/lib/python3.11/site-packages/requests/api.py", line 73, in get
    return request("get", url, params=params, **kwargs)
           ^^^^^^^^^^^^^^^^^^^^^^^^^^^^^^^^^^^^^^^^^^^^
  File "/home/ccl/anaconda3/envs/fedops_hyp/lib/python3.11/site-packages/requests/api.py", line 59, in request
    return session.request(method=method, url=url, **kwargs)
           ^^^^^^^^^^^^^^^^^^^^^^^^^^^^^^^^^^^^^^^^^^^^^^^^^
  File "/home/ccl/anaconda3/envs/fedops_hyp/lib/python3.11/site-packages/requests/sessions.py", line 589, in request
    resp = self.send(prep, **send_kwargs)
           ^^^^^^^^^^^^^^^^^^^^^^^^^^^^^^
  File "/home/ccl/anaconda3/envs/fedops_hyp/lib/python3.11/site-packages/requests/sessions.py", line 703, in send
    r = adapter.send(request, **kwargs)
        ^^^^^^^^^^^^^^^^^^^^^^^^^^^^^^^
  File "/home/ccl/anaconda3/envs/fedops_hyp/lib/python3.11/site-packages/requests/adapters.py", line 700, in send
    raise ConnectionError(e, request=request)
requests.exceptions.ConnectionError: HTTPConnectionPool(host='localhost', port=8004): Max retries exceeded with url: /flclient_out (Caused by NewConnectionError('<urllib3.connection.HTTPConnection object at 0x7fb343140750>: Failed to establish a new connection: [Errno 111] Connection refused'))

Set the environment variable HYDRA_FULL_ERROR=1 for a complete stack trace.
